2021-02-28 14:06:41 [ERROR] : 获取 [CNVD] 威胁情报异常
Traceback (most recent call last):
  File "/home/runner/work/threat-broadcast/threat-broadcast/src/crawler/_base_crawler.py", line 64, in cves
    new_cves = self.get_cves()
  File "/home/runner/work/threat-broadcast/threat-broadcast/src/crawler/cnvd.py", line 63, in get_cves
    log.warn('获取 [%s] 威胁情报失败： [HTTP Error %i] 服务器返回内容：[%s]' % (self.NAME_CH(), response.status_code),response.text)
TypeError: not enough arguments for format string
2021-02-28 14:06:41 [ERROR] : Traceback (most recent call last):
  File "/home/runner/work/threat-broadcast/threat-broadcast/src/crawler/_base_crawler.py", line 64, in cves
    new_cves = self.get_cves()
  File "/home/runner/work/threat-broadcast/threat-broadcast/src/crawler/cnvd.py", line 63, in get_cves
    log.warn('获取 [%s] 威胁情报失败： [HTTP Error %i] 服务器返回内容：[%s]' % (self.NAME_CH(), response.status_code),response.text)
TypeError: not enough arguments for format string
Traceback (most recent call last):
  File "/home/runner/work/threat-broadcast/threat-broadcast/src/crawler/_base_crawler.py", line 64, in cves
    new_cves = self.get_cves()
  File "/home/runner/work/threat-broadcast/threat-broadcast/src/crawler/cnvd.py", line 63, in get_cves
    log.warn('获取 [%s] 威胁情报失败： [HTTP Error %i] 服务器返回内容：[%s]' % (self.NAME_CH(), response.status_code),response.text)
TypeError: not enough arguments for format string
2021-02-28 14:19:40 [ERROR] : 获取 [CNVD] 威胁情报异常
Traceback (most recent call last):
  File "/home/runner/work/threat-broadcast/threat-broadcast/src/crawler/_base_crawler.py", line 64, in cves
    new_cves = self.get_cves()
  File "/home/runner/work/threat-broadcast/threat-broadcast/src/crawler/cnvd.py", line 63, in get_cves
    log.warn('获取 [%s] 威胁情报失败： [HTTP Error %i] 服务器返回内容：[%s]' % (self.NAME_CH(), response.status_code),response.text)
TypeError: not enough arguments for format string
2021-02-28 14:19:40 [ERROR] : Traceback (most recent call last):
  File "/home/runner/work/threat-broadcast/threat-broadcast/src/crawler/_base_crawler.py", line 64, in cves
    new_cves = self.get_cves()
  File "/home/runner/work/threat-broadcast/threat-broadcast/src/crawler/cnvd.py", line 63, in get_cves
    log.warn('获取 [%s] 威胁情报失败： [HTTP Error %i] 服务器返回内容：[%s]' % (self.NAME_CH(), response.status_code),response.text)
TypeError: not enough arguments for format string
Traceback (most recent call last):
  File "/home/runner/work/threat-broadcast/threat-broadcast/src/crawler/_base_crawler.py", line 64, in cves
    new_cves = self.get_cves()
  File "/home/runner/work/threat-broadcast/threat-broadcast/src/crawler/cnvd.py", line 63, in get_cves
    log.warn('获取 [%s] 威胁情报失败： [HTTP Error %i] 服务器返回内容：[%s]' % (self.NAME_CH(), response.status_code),response.text)
TypeError: not enough arguments for format string
2021-02-28 14:21:43 [ERROR] : 获取 [安全客] 威胁情报异常
Traceback (most recent call last):
  File "/opt/hostedtoolcache/Python/3.8.7/x64/lib/python3.8/site-packages/urllib3/connectionpool.py", line 381, in _make_request
    self._validate_conn(conn)
  File "/opt/hostedtoolcache/Python/3.8.7/x64/lib/python3.8/site-packages/urllib3/connectionpool.py", line 978, in _validate_conn
    conn.connect()
  File "/opt/hostedtoolcache/Python/3.8.7/x64/lib/python3.8/site-packages/urllib3/connection.py", line 362, in connect
    self.sock = ssl_wrap_socket(
  File "/opt/hostedtoolcache/Python/3.8.7/x64/lib/python3.8/site-packages/urllib3/util/ssl_.py", line 386, in ssl_wrap_socket
    return context.wrap_socket(sock, server_hostname=server_hostname)
  File "/opt/hostedtoolcache/Python/3.8.7/x64/lib/python3.8/ssl.py", line 500, in wrap_socket
    return self.sslsocket_class._create(
  File "/opt/hostedtoolcache/Python/3.8.7/x64/lib/python3.8/ssl.py", line 1040, in _create
    self.do_handshake()
  File "/opt/hostedtoolcache/Python/3.8.7/x64/lib/python3.8/ssl.py", line 1309, in do_handshake
    self._sslobj.do_handshake()
socket.timeout: _ssl.c:1108: The handshake operation timed out

During handling of the above exception, another exception occurred:

Traceback (most recent call last):
  File "/opt/hostedtoolcache/Python/3.8.7/x64/lib/python3.8/site-packages/requests/adapters.py", line 439, in send
    resp = conn.urlopen(
  File "/opt/hostedtoolcache/Python/3.8.7/x64/lib/python3.8/site-packages/urllib3/connectionpool.py", line 726, in urlopen
    retries = retries.increment(
  File "/opt/hostedtoolcache/Python/3.8.7/x64/lib/python3.8/site-packages/urllib3/util/retry.py", line 410, in increment
    raise six.reraise(type(error), error, _stacktrace)
  File "/opt/hostedtoolcache/Python/3.8.7/x64/lib/python3.8/site-packages/urllib3/packages/six.py", line 735, in reraise
    raise value
  File "/opt/hostedtoolcache/Python/3.8.7/x64/lib/python3.8/site-packages/urllib3/connectionpool.py", line 670, in urlopen
    httplib_response = self._make_request(
  File "/opt/hostedtoolcache/Python/3.8.7/x64/lib/python3.8/site-packages/urllib3/connectionpool.py", line 384, in _make_request
    self._raise_timeout(err=e, url=url, timeout_value=conn.timeout)
  File "/opt/hostedtoolcache/Python/3.8.7/x64/lib/python3.8/site-packages/urllib3/connectionpool.py", line 335, in _raise_timeout
    raise ReadTimeoutError(
urllib3.exceptions.ReadTimeoutError: HTTPSConnectionPool(host='www.anquanke.com', port=443): Read timed out. (read timeout=60)

During handling of the above exception, another exception occurred:

Traceback (most recent call last):
  File "/home/runner/work/threat-broadcast/threat-broadcast/src/crawler/_base_crawler.py", line 64, in cves
    new_cves = self.get_cves()
  File "/home/runner/work/threat-broadcast/threat-broadcast/src/crawler/anquanke.py", line 41, in get_cves
    response = requests.get(
  File "/opt/hostedtoolcache/Python/3.8.7/x64/lib/python3.8/site-packages/requests/api.py", line 75, in get
    return request('get', url, params=params, **kwargs)
  File "/opt/hostedtoolcache/Python/3.8.7/x64/lib/python3.8/site-packages/requests/api.py", line 60, in request
    return session.request(method=method, url=url, **kwargs)
  File "/opt/hostedtoolcache/Python/3.8.7/x64/lib/python3.8/site-packages/requests/sessions.py", line 533, in request
    resp = self.send(prep, **send_kwargs)
  File "/opt/hostedtoolcache/Python/3.8.7/x64/lib/python3.8/site-packages/requests/sessions.py", line 646, in send
    r = adapter.send(request, **kwargs)
  File "/opt/hostedtoolcache/Python/3.8.7/x64/lib/python3.8/site-packages/requests/adapters.py", line 529, in send
    raise ReadTimeout(e, request=request)
requests.exceptions.ReadTimeout: HTTPSConnectionPool(host='www.anquanke.com', port=443): Read timed out. (read timeout=60)
2021-02-28 14:21:43 [ERROR] : Traceback (most recent call last):
  File "/opt/hostedtoolcache/Python/3.8.7/x64/lib/python3.8/site-packages/urllib3/connectionpool.py", line 381, in _make_request
    self._validate_conn(conn)
  File "/opt/hostedtoolcache/Python/3.8.7/x64/lib/python3.8/site-packages/urllib3/connectionpool.py", line 978, in _validate_conn
    conn.connect()
  File "/opt/hostedtoolcache/Python/3.8.7/x64/lib/python3.8/site-packages/urllib3/connection.py", line 362, in connect
    self.sock = ssl_wrap_socket(
  File "/opt/hostedtoolcache/Python/3.8.7/x64/lib/python3.8/site-packages/urllib3/util/ssl_.py", line 386, in ssl_wrap_socket
    return context.wrap_socket(sock, server_hostname=server_hostname)
  File "/opt/hostedtoolcache/Python/3.8.7/x64/lib/python3.8/ssl.py", line 500, in wrap_socket
    return self.sslsocket_class._create(
  File "/opt/hostedtoolcache/Python/3.8.7/x64/lib/python3.8/ssl.py", line 1040, in _create
    self.do_handshake()
  File "/opt/hostedtoolcache/Python/3.8.7/x64/lib/python3.8/ssl.py", line 1309, in do_handshake
    self._sslobj.do_handshake()
socket.timeout: _ssl.c:1108: The handshake operation timed out

During handling of the above exception, another exception occurred:

Traceback (most recent call last):
  File "/opt/hostedtoolcache/Python/3.8.7/x64/lib/python3.8/site-packages/requests/adapters.py", line 439, in send
    resp = conn.urlopen(
  File "/opt/hostedtoolcache/Python/3.8.7/x64/lib/python3.8/site-packages/urllib3/connectionpool.py", line 726, in urlopen
    retries = retries.increment(
  File "/opt/hostedtoolcache/Python/3.8.7/x64/lib/python3.8/site-packages/urllib3/util/retry.py", line 410, in increment
    raise six.reraise(type(error), error, _stacktrace)
  File "/opt/hostedtoolcache/Python/3.8.7/x64/lib/python3.8/site-packages/urllib3/packages/six.py", line 735, in reraise
    raise value
  File "/opt/hostedtoolcache/Python/3.8.7/x64/lib/python3.8/site-packages/urllib3/connectionpool.py", line 670, in urlopen
    httplib_response = self._make_request(
  File "/opt/hostedtoolcache/Python/3.8.7/x64/lib/python3.8/site-packages/urllib3/connectionpool.py", line 384, in _make_request
    self._raise_timeout(err=e, url=url, timeout_value=conn.timeout)
  File "/opt/hostedtoolcache/Python/3.8.7/x64/lib/python3.8/site-packages/urllib3/connectionpool.py", line 335, in _raise_timeout
    raise ReadTimeoutError(
urllib3.exceptions.ReadTimeoutError: HTTPSConnectionPool(host='www.anquanke.com', port=443): Read timed out. (read timeout=60)

During handling of the above exception, another exception occurred:

Traceback (most recent call last):
  File "/home/runner/work/threat-broadcast/threat-broadcast/src/crawler/_base_crawler.py", line 64, in cves
    new_cves = self.get_cves()
  File "/home/runner/work/threat-broadcast/threat-broadcast/src/crawler/anquanke.py", line 41, in get_cves
    response = requests.get(
  File "/opt/hostedtoolcache/Python/3.8.7/x64/lib/python3.8/site-packages/requests/api.py", line 75, in get
    return request('get', url, params=params, **kwargs)
  File "/opt/hostedtoolcache/Python/3.8.7/x64/lib/python3.8/site-packages/requests/api.py", line 60, in request
    return session.request(method=method, url=url, **kwargs)
  File "/opt/hostedtoolcache/Python/3.8.7/x64/lib/python3.8/site-packages/requests/sessions.py", line 533, in request
    resp = self.send(prep, **send_kwargs)
  File "/opt/hostedtoolcache/Python/3.8.7/x64/lib/python3.8/site-packages/requests/sessions.py", line 646, in send
    r = adapter.send(request, **kwargs)
  File "/opt/hostedtoolcache/Python/3.8.7/x64/lib/python3.8/site-packages/requests/adapters.py", line 529, in send
    raise ReadTimeout(e, request=request)
requests.exceptions.ReadTimeout: HTTPSConnectionPool(host='www.anquanke.com', port=443): Read timed out. (read timeout=60)
Traceback (most recent call last):
  File "/opt/hostedtoolcache/Python/3.8.7/x64/lib/python3.8/site-packages/urllib3/connectionpool.py", line 381, in _make_request
    self._validate_conn(conn)
  File "/opt/hostedtoolcache/Python/3.8.7/x64/lib/python3.8/site-packages/urllib3/connectionpool.py", line 978, in _validate_conn
    conn.connect()
  File "/opt/hostedtoolcache/Python/3.8.7/x64/lib/python3.8/site-packages/urllib3/connection.py", line 362, in connect
    self.sock = ssl_wrap_socket(
  File "/opt/hostedtoolcache/Python/3.8.7/x64/lib/python3.8/site-packages/urllib3/util/ssl_.py", line 386, in ssl_wrap_socket
    return context.wrap_socket(sock, server_hostname=server_hostname)
  File "/opt/hostedtoolcache/Python/3.8.7/x64/lib/python3.8/ssl.py", line 500, in wrap_socket
    return self.sslsocket_class._create(
  File "/opt/hostedtoolcache/Python/3.8.7/x64/lib/python3.8/ssl.py", line 1040, in _create
    self.do_handshake()
  File "/opt/hostedtoolcache/Python/3.8.7/x64/lib/python3.8/ssl.py", line 1309, in do_handshake
    self._sslobj.do_handshake()
socket.timeout: _ssl.c:1108: The handshake operation timed out

During handling of the above exception, another exception occurred:

Traceback (most recent call last):
  File "/opt/hostedtoolcache/Python/3.8.7/x64/lib/python3.8/site-packages/requests/adapters.py", line 439, in send
    resp = conn.urlopen(
  File "/opt/hostedtoolcache/Python/3.8.7/x64/lib/python3.8/site-packages/urllib3/connectionpool.py", line 726, in urlopen
    retries = retries.increment(
  File "/opt/hostedtoolcache/Python/3.8.7/x64/lib/python3.8/site-packages/urllib3/util/retry.py", line 410, in increment
    raise six.reraise(type(error), error, _stacktrace)
  File "/opt/hostedtoolcache/Python/3.8.7/x64/lib/python3.8/site-packages/urllib3/packages/six.py", line 735, in reraise
    raise value
  File "/opt/hostedtoolcache/Python/3.8.7/x64/lib/python3.8/site-packages/urllib3/connectionpool.py", line 670, in urlopen
    httplib_response = self._make_request(
  File "/opt/hostedtoolcache/Python/3.8.7/x64/lib/python3.8/site-packages/urllib3/connectionpool.py", line 384, in _make_request
    self._raise_timeout(err=e, url=url, timeout_value=conn.timeout)
  File "/opt/hostedtoolcache/Python/3.8.7/x64/lib/python3.8/site-packages/urllib3/connectionpool.py", line 335, in _raise_timeout
    raise ReadTimeoutError(
urllib3.exceptions.ReadTimeoutError: HTTPSConnectionPool(host='www.anquanke.com', port=443): Read timed out. (read timeout=60)

During handling of the above exception, another exception occurred:

Traceback (most recent call last):
  File "/home/runner/work/threat-broadcast/threat-broadcast/src/crawler/_base_crawler.py", line 64, in cves
    new_cves = self.get_cves()
  File "/home/runner/work/threat-broadcast/threat-broadcast/src/crawler/anquanke.py", line 41, in get_cves
    response = requests.get(
  File "/opt/hostedtoolcache/Python/3.8.7/x64/lib/python3.8/site-packages/requests/api.py", line 75, in get
    return request('get', url, params=params, **kwargs)
  File "/opt/hostedtoolcache/Python/3.8.7/x64/lib/python3.8/site-packages/requests/api.py", line 60, in request
    return session.request(method=method, url=url, **kwargs)
  File "/opt/hostedtoolcache/Python/3.8.7/x64/lib/python3.8/site-packages/requests/sessions.py", line 533, in request
    resp = self.send(prep, **send_kwargs)
  File "/opt/hostedtoolcache/Python/3.8.7/x64/lib/python3.8/site-packages/requests/sessions.py", line 646, in send
    r = adapter.send(request, **kwargs)
  File "/opt/hostedtoolcache/Python/3.8.7/x64/lib/python3.8/site-packages/requests/adapters.py", line 529, in send
    raise ReadTimeout(e, request=request)
requests.exceptions.ReadTimeout: HTTPSConnectionPool(host='www.anquanke.com', port=443): Read timed out. (read timeout=60)
