2021-02-27 03:30:53 [INFO] : ++++++++++++++++++++++++++++++++++++++++++++
2021-02-27 03:30:53 [INFO] : 正在获取 [360] 威胁情报...
2021-02-27 03:30:55 [INFO] : 得到 [360] 最新威胁情报 [0] 条
2021-02-27 03:30:55 [INFO] : --------------------------------------------
2021-02-27 03:30:55 [INFO] : ++++++++++++++++++++++++++++++++++++++++++++
2021-02-27 03:30:55 [INFO] : 正在获取 [绿盟] 威胁情报...
2021-02-27 03:31:41 [INFO] : 得到 [绿盟] 最新威胁情报 [0] 条
2021-02-27 03:31:41 [INFO] : --------------------------------------------
2021-02-27 03:31:41 [INFO] : ++++++++++++++++++++++++++++++++++++++++++++
2021-02-27 03:31:41 [INFO] : 正在获取 [奇安信] 威胁情报...
2021-02-27 03:31:43 [INFO] : 得到 [奇安信] 最新威胁情报 [0] 条
2021-02-27 03:31:43 [INFO] : --------------------------------------------
2021-02-27 03:31:43 [INFO] : ++++++++++++++++++++++++++++++++++++++++++++
2021-02-27 03:31:43 [INFO] : 正在获取 [红后] 威胁情报...
2021-02-27 03:31:46 [INFO] : 得到 [红后] 最新威胁情报 [0] 条
2021-02-27 03:31:46 [INFO] : --------------------------------------------
2021-02-27 03:31:46 [INFO] : ++++++++++++++++++++++++++++++++++++++++++++
2021-02-27 03:31:46 [INFO] : 正在获取 [安全客] 威胁情报...
2021-02-27 03:31:49 [INFO] : 得到 [安全客] 最新威胁情报 [0] 条
2021-02-27 03:31:49 [INFO] : --------------------------------------------
2021-02-27 03:31:49 [INFO] : ++++++++++++++++++++++++++++++++++++++++++++
2021-02-27 03:31:49 [INFO] : 正在获取 [斗象] 威胁情报...
2021-02-27 03:31:57 [INFO] : 得到 [斗象] 最新威胁情报 [0] 条
2021-02-27 03:31:57 [INFO] : --------------------------------------------
2021-02-27 03:31:57 [INFO] : ++++++++++++++++++++++++++++++++++++++++++++
2021-02-27 03:31:57 [INFO] : 正在获取 [CNVD] 威胁情报...
2021-02-27 03:31:59 [WARNING] : 获取 [CNVD] 威胁情报失败： [HTTP Error 521]
2021-02-27 03:31:59 [INFO] : 得到 [CNVD] 最新威胁情报 [0] 条
2021-02-27 03:31:59 [INFO] : --------------------------------------------
2021-02-27 04:36:42 [INFO] : ++++++++++++++++++++++++++++++++++++++++++++
2021-02-27 04:36:42 [INFO] : 正在获取 [360] 威胁情报...
2021-02-27 04:36:43 [INFO] : 得到 [360] 最新威胁情报 [0] 条
2021-02-27 04:36:43 [INFO] : --------------------------------------------
2021-02-27 04:36:43 [INFO] : ++++++++++++++++++++++++++++++++++++++++++++
2021-02-27 04:36:43 [INFO] : 正在获取 [绿盟] 威胁情报...
2021-02-27 04:36:44 [INFO] : 得到 [绿盟] 最新威胁情报 [0] 条
2021-02-27 04:36:44 [INFO] : --------------------------------------------
2021-02-27 04:36:44 [INFO] : ++++++++++++++++++++++++++++++++++++++++++++
2021-02-27 04:36:44 [INFO] : 正在获取 [奇安信] 威胁情报...
2021-02-27 04:36:49 [INFO] : 得到 [奇安信] 最新威胁情报 [0] 条
2021-02-27 04:36:49 [INFO] : --------------------------------------------
2021-02-27 04:36:49 [INFO] : ++++++++++++++++++++++++++++++++++++++++++++
2021-02-27 04:36:49 [INFO] : 正在获取 [红后] 威胁情报...
2021-02-27 04:36:51 [INFO] : 得到 [红后] 最新威胁情报 [0] 条
2021-02-27 04:36:51 [INFO] : --------------------------------------------
2021-02-27 04:36:51 [INFO] : ++++++++++++++++++++++++++++++++++++++++++++
2021-02-27 04:36:51 [INFO] : 正在获取 [安全客] 威胁情报...
2021-02-27 04:36:56 [INFO] : 得到 [安全客] 最新威胁情报 [0] 条
2021-02-27 04:36:56 [INFO] : --------------------------------------------
2021-02-27 04:36:56 [INFO] : ++++++++++++++++++++++++++++++++++++++++++++
2021-02-27 04:36:56 [INFO] : 正在获取 [斗象] 威胁情报...
2021-02-27 04:37:03 [INFO] : 得到 [斗象] 最新威胁情报 [0] 条
2021-02-27 04:37:03 [INFO] : --------------------------------------------
2021-02-27 04:37:03 [INFO] : ++++++++++++++++++++++++++++++++++++++++++++
2021-02-27 04:37:03 [INFO] : 正在获取 [CNVD] 威胁情报...
2021-02-27 04:37:05 [WARNING] : 获取 [CNVD] 威胁情报失败： [HTTP Error 521]
2021-02-27 04:37:05 [INFO] : 得到 [CNVD] 最新威胁情报 [0] 条
2021-02-27 04:37:05 [INFO] : --------------------------------------------
2021-02-27 05:28:44 [INFO] : ++++++++++++++++++++++++++++++++++++++++++++
2021-02-27 05:28:44 [INFO] : 正在获取 [360] 威胁情报...
2021-02-27 05:28:45 [INFO] : 得到 [360] 最新威胁情报 [0] 条
2021-02-27 05:28:45 [INFO] : --------------------------------------------
2021-02-27 05:28:45 [INFO] : ++++++++++++++++++++++++++++++++++++++++++++
2021-02-27 05:28:45 [INFO] : 正在获取 [绿盟] 威胁情报...
2021-02-27 05:28:46 [INFO] : 得到 [绿盟] 最新威胁情报 [0] 条
2021-02-27 05:28:46 [INFO] : --------------------------------------------
2021-02-27 05:28:46 [INFO] : ++++++++++++++++++++++++++++++++++++++++++++
2021-02-27 05:28:46 [INFO] : 正在获取 [奇安信] 威胁情报...
2021-02-27 05:28:53 [INFO] : 得到 [奇安信] 最新威胁情报 [0] 条
2021-02-27 05:28:53 [INFO] : --------------------------------------------
2021-02-27 05:28:53 [INFO] : ++++++++++++++++++++++++++++++++++++++++++++
2021-02-27 05:28:53 [INFO] : 正在获取 [红后] 威胁情报...
2021-02-27 05:28:56 [INFO] : 得到 [红后] 最新威胁情报 [0] 条
2021-02-27 05:28:56 [INFO] : --------------------------------------------
2021-02-27 05:28:56 [INFO] : ++++++++++++++++++++++++++++++++++++++++++++
2021-02-27 05:28:56 [INFO] : 正在获取 [安全客] 威胁情报...
2021-02-27 05:29:58 [ERROR] : 获取 [安全客] 威胁情报异常
Traceback (most recent call last):
  File "/opt/hostedtoolcache/Python/3.8.7/x64/lib/python3.8/site-packages/urllib3/connectionpool.py", line 381, in _make_request
    self._validate_conn(conn)
  File "/opt/hostedtoolcache/Python/3.8.7/x64/lib/python3.8/site-packages/urllib3/connectionpool.py", line 978, in _validate_conn
    conn.connect()
  File "/opt/hostedtoolcache/Python/3.8.7/x64/lib/python3.8/site-packages/urllib3/connection.py", line 362, in connect
    self.sock = ssl_wrap_socket(
  File "/opt/hostedtoolcache/Python/3.8.7/x64/lib/python3.8/site-packages/urllib3/util/ssl_.py", line 386, in ssl_wrap_socket
    return context.wrap_socket(sock, server_hostname=server_hostname)
  File "/opt/hostedtoolcache/Python/3.8.7/x64/lib/python3.8/ssl.py", line 500, in wrap_socket
    return self.sslsocket_class._create(
  File "/opt/hostedtoolcache/Python/3.8.7/x64/lib/python3.8/ssl.py", line 1040, in _create
    self.do_handshake()
  File "/opt/hostedtoolcache/Python/3.8.7/x64/lib/python3.8/ssl.py", line 1309, in do_handshake
    self._sslobj.do_handshake()
socket.timeout: _ssl.c:1108: The handshake operation timed out

During handling of the above exception, another exception occurred:

Traceback (most recent call last):
  File "/opt/hostedtoolcache/Python/3.8.7/x64/lib/python3.8/site-packages/requests/adapters.py", line 439, in send
    resp = conn.urlopen(
  File "/opt/hostedtoolcache/Python/3.8.7/x64/lib/python3.8/site-packages/urllib3/connectionpool.py", line 726, in urlopen
    retries = retries.increment(
  File "/opt/hostedtoolcache/Python/3.8.7/x64/lib/python3.8/site-packages/urllib3/util/retry.py", line 410, in increment
    raise six.reraise(type(error), error, _stacktrace)
  File "/opt/hostedtoolcache/Python/3.8.7/x64/lib/python3.8/site-packages/urllib3/packages/six.py", line 735, in reraise
    raise value
  File "/opt/hostedtoolcache/Python/3.8.7/x64/lib/python3.8/site-packages/urllib3/connectionpool.py", line 670, in urlopen
    httplib_response = self._make_request(
  File "/opt/hostedtoolcache/Python/3.8.7/x64/lib/python3.8/site-packages/urllib3/connectionpool.py", line 384, in _make_request
    self._raise_timeout(err=e, url=url, timeout_value=conn.timeout)
  File "/opt/hostedtoolcache/Python/3.8.7/x64/lib/python3.8/site-packages/urllib3/connectionpool.py", line 335, in _raise_timeout
    raise ReadTimeoutError(
urllib3.exceptions.ReadTimeoutError: HTTPSConnectionPool(host='www.anquanke.com', port=443): Read timed out. (read timeout=60)

During handling of the above exception, another exception occurred:

Traceback (most recent call last):
  File "/home/runner/work/threat-broadcast/threat-broadcast/src/crawler/_base_crawler.py", line 62, in cves
    new_cves = self.get_cves()
  File "/home/runner/work/threat-broadcast/threat-broadcast/src/crawler/anquanke.py", line 41, in get_cves
    response = requests.get(
  File "/opt/hostedtoolcache/Python/3.8.7/x64/lib/python3.8/site-packages/requests/api.py", line 75, in get
    return request('get', url, params=params, **kwargs)
  File "/opt/hostedtoolcache/Python/3.8.7/x64/lib/python3.8/site-packages/requests/api.py", line 60, in request
    return session.request(method=method, url=url, **kwargs)
  File "/opt/hostedtoolcache/Python/3.8.7/x64/lib/python3.8/site-packages/requests/sessions.py", line 533, in request
    resp = self.send(prep, **send_kwargs)
  File "/opt/hostedtoolcache/Python/3.8.7/x64/lib/python3.8/site-packages/requests/sessions.py", line 646, in send
    r = adapter.send(request, **kwargs)
  File "/opt/hostedtoolcache/Python/3.8.7/x64/lib/python3.8/site-packages/requests/adapters.py", line 529, in send
    raise ReadTimeout(e, request=request)
requests.exceptions.ReadTimeout: HTTPSConnectionPool(host='www.anquanke.com', port=443): Read timed out. (read timeout=60)
2021-02-27 05:29:58 [ERROR] : Traceback (most recent call last):
  File "/opt/hostedtoolcache/Python/3.8.7/x64/lib/python3.8/site-packages/urllib3/connectionpool.py", line 381, in _make_request
    self._validate_conn(conn)
  File "/opt/hostedtoolcache/Python/3.8.7/x64/lib/python3.8/site-packages/urllib3/connectionpool.py", line 978, in _validate_conn
    conn.connect()
  File "/opt/hostedtoolcache/Python/3.8.7/x64/lib/python3.8/site-packages/urllib3/connection.py", line 362, in connect
    self.sock = ssl_wrap_socket(
  File "/opt/hostedtoolcache/Python/3.8.7/x64/lib/python3.8/site-packages/urllib3/util/ssl_.py", line 386, in ssl_wrap_socket
    return context.wrap_socket(sock, server_hostname=server_hostname)
  File "/opt/hostedtoolcache/Python/3.8.7/x64/lib/python3.8/ssl.py", line 500, in wrap_socket
    return self.sslsocket_class._create(
  File "/opt/hostedtoolcache/Python/3.8.7/x64/lib/python3.8/ssl.py", line 1040, in _create
    self.do_handshake()
  File "/opt/hostedtoolcache/Python/3.8.7/x64/lib/python3.8/ssl.py", line 1309, in do_handshake
    self._sslobj.do_handshake()
socket.timeout: _ssl.c:1108: The handshake operation timed out

During handling of the above exception, another exception occurred:

Traceback (most recent call last):
  File "/opt/hostedtoolcache/Python/3.8.7/x64/lib/python3.8/site-packages/requests/adapters.py", line 439, in send
    resp = conn.urlopen(
  File "/opt/hostedtoolcache/Python/3.8.7/x64/lib/python3.8/site-packages/urllib3/connectionpool.py", line 726, in urlopen
    retries = retries.increment(
  File "/opt/hostedtoolcache/Python/3.8.7/x64/lib/python3.8/site-packages/urllib3/util/retry.py", line 410, in increment
    raise six.reraise(type(error), error, _stacktrace)
  File "/opt/hostedtoolcache/Python/3.8.7/x64/lib/python3.8/site-packages/urllib3/packages/six.py", line 735, in reraise
    raise value
  File "/opt/hostedtoolcache/Python/3.8.7/x64/lib/python3.8/site-packages/urllib3/connectionpool.py", line 670, in urlopen
    httplib_response = self._make_request(
  File "/opt/hostedtoolcache/Python/3.8.7/x64/lib/python3.8/site-packages/urllib3/connectionpool.py", line 384, in _make_request
    self._raise_timeout(err=e, url=url, timeout_value=conn.timeout)
  File "/opt/hostedtoolcache/Python/3.8.7/x64/lib/python3.8/site-packages/urllib3/connectionpool.py", line 335, in _raise_timeout
    raise ReadTimeoutError(
urllib3.exceptions.ReadTimeoutError: HTTPSConnectionPool(host='www.anquanke.com', port=443): Read timed out. (read timeout=60)

During handling of the above exception, another exception occurred:

Traceback (most recent call last):
  File "/home/runner/work/threat-broadcast/threat-broadcast/src/crawler/_base_crawler.py", line 62, in cves
    new_cves = self.get_cves()
  File "/home/runner/work/threat-broadcast/threat-broadcast/src/crawler/anquanke.py", line 41, in get_cves
    response = requests.get(
  File "/opt/hostedtoolcache/Python/3.8.7/x64/lib/python3.8/site-packages/requests/api.py", line 75, in get
    return request('get', url, params=params, **kwargs)
  File "/opt/hostedtoolcache/Python/3.8.7/x64/lib/python3.8/site-packages/requests/api.py", line 60, in request
    return session.request(method=method, url=url, **kwargs)
  File "/opt/hostedtoolcache/Python/3.8.7/x64/lib/python3.8/site-packages/requests/sessions.py", line 533, in request
    resp = self.send(prep, **send_kwargs)
  File "/opt/hostedtoolcache/Python/3.8.7/x64/lib/python3.8/site-packages/requests/sessions.py", line 646, in send
    r = adapter.send(request, **kwargs)
  File "/opt/hostedtoolcache/Python/3.8.7/x64/lib/python3.8/site-packages/requests/adapters.py", line 529, in send
    raise ReadTimeout(e, request=request)
requests.exceptions.ReadTimeout: HTTPSConnectionPool(host='www.anquanke.com', port=443): Read timed out. (read timeout=60)
Traceback (most recent call last):
  File "/opt/hostedtoolcache/Python/3.8.7/x64/lib/python3.8/site-packages/urllib3/connectionpool.py", line 381, in _make_request
    self._validate_conn(conn)
  File "/opt/hostedtoolcache/Python/3.8.7/x64/lib/python3.8/site-packages/urllib3/connectionpool.py", line 978, in _validate_conn
    conn.connect()
  File "/opt/hostedtoolcache/Python/3.8.7/x64/lib/python3.8/site-packages/urllib3/connection.py", line 362, in connect
    self.sock = ssl_wrap_socket(
  File "/opt/hostedtoolcache/Python/3.8.7/x64/lib/python3.8/site-packages/urllib3/util/ssl_.py", line 386, in ssl_wrap_socket
    return context.wrap_socket(sock, server_hostname=server_hostname)
  File "/opt/hostedtoolcache/Python/3.8.7/x64/lib/python3.8/ssl.py", line 500, in wrap_socket
    return self.sslsocket_class._create(
  File "/opt/hostedtoolcache/Python/3.8.7/x64/lib/python3.8/ssl.py", line 1040, in _create
    self.do_handshake()
  File "/opt/hostedtoolcache/Python/3.8.7/x64/lib/python3.8/ssl.py", line 1309, in do_handshake
    self._sslobj.do_handshake()
socket.timeout: _ssl.c:1108: The handshake operation timed out

During handling of the above exception, another exception occurred:

Traceback (most recent call last):
  File "/opt/hostedtoolcache/Python/3.8.7/x64/lib/python3.8/site-packages/requests/adapters.py", line 439, in send
    resp = conn.urlopen(
  File "/opt/hostedtoolcache/Python/3.8.7/x64/lib/python3.8/site-packages/urllib3/connectionpool.py", line 726, in urlopen
    retries = retries.increment(
  File "/opt/hostedtoolcache/Python/3.8.7/x64/lib/python3.8/site-packages/urllib3/util/retry.py", line 410, in increment
    raise six.reraise(type(error), error, _stacktrace)
  File "/opt/hostedtoolcache/Python/3.8.7/x64/lib/python3.8/site-packages/urllib3/packages/six.py", line 735, in reraise
    raise value
  File "/opt/hostedtoolcache/Python/3.8.7/x64/lib/python3.8/site-packages/urllib3/connectionpool.py", line 670, in urlopen
    httplib_response = self._make_request(
  File "/opt/hostedtoolcache/Python/3.8.7/x64/lib/python3.8/site-packages/urllib3/connectionpool.py", line 384, in _make_request
    self._raise_timeout(err=e, url=url, timeout_value=conn.timeout)
  File "/opt/hostedtoolcache/Python/3.8.7/x64/lib/python3.8/site-packages/urllib3/connectionpool.py", line 335, in _raise_timeout
    raise ReadTimeoutError(
urllib3.exceptions.ReadTimeoutError: HTTPSConnectionPool(host='www.anquanke.com', port=443): Read timed out. (read timeout=60)

During handling of the above exception, another exception occurred:

Traceback (most recent call last):
  File "/home/runner/work/threat-broadcast/threat-broadcast/src/crawler/_base_crawler.py", line 62, in cves
    new_cves = self.get_cves()
  File "/home/runner/work/threat-broadcast/threat-broadcast/src/crawler/anquanke.py", line 41, in get_cves
    response = requests.get(
  File "/opt/hostedtoolcache/Python/3.8.7/x64/lib/python3.8/site-packages/requests/api.py", line 75, in get
    return request('get', url, params=params, **kwargs)
  File "/opt/hostedtoolcache/Python/3.8.7/x64/lib/python3.8/site-packages/requests/api.py", line 60, in request
    return session.request(method=method, url=url, **kwargs)
  File "/opt/hostedtoolcache/Python/3.8.7/x64/lib/python3.8/site-packages/requests/sessions.py", line 533, in request
    resp = self.send(prep, **send_kwargs)
  File "/opt/hostedtoolcache/Python/3.8.7/x64/lib/python3.8/site-packages/requests/sessions.py", line 646, in send
    r = adapter.send(request, **kwargs)
  File "/opt/hostedtoolcache/Python/3.8.7/x64/lib/python3.8/site-packages/requests/adapters.py", line 529, in send
    raise ReadTimeout(e, request=request)
requests.exceptions.ReadTimeout: HTTPSConnectionPool(host='www.anquanke.com', port=443): Read timed out. (read timeout=60)
2021-02-27 05:29:58 [INFO] : 得到 [安全客] 最新威胁情报 [0] 条
2021-02-27 05:29:58 [INFO] : --------------------------------------------
2021-02-27 05:29:58 [INFO] : ++++++++++++++++++++++++++++++++++++++++++++
2021-02-27 05:29:58 [INFO] : 正在获取 [斗象] 威胁情报...
2021-02-27 05:30:07 [INFO] : 得到 [斗象] 最新威胁情报 [0] 条
2021-02-27 05:30:07 [INFO] : --------------------------------------------
2021-02-27 05:30:07 [INFO] : ++++++++++++++++++++++++++++++++++++++++++++
2021-02-27 05:30:07 [INFO] : 正在获取 [CNVD] 威胁情报...
2021-02-27 05:30:11 [WARNING] : 获取 [CNVD] 威胁情报失败： [HTTP Error 521]
2021-02-27 05:30:11 [INFO] : 得到 [CNVD] 最新威胁情报 [0] 条
2021-02-27 05:30:11 [INFO] : --------------------------------------------
2021-02-27 06:33:11 [INFO] : ++++++++++++++++++++++++++++++++++++++++++++
2021-02-27 06:33:11 [INFO] : 正在获取 [360] 威胁情报...
2021-02-27 06:33:13 [INFO] : 得到 [360] 最新威胁情报 [0] 条
2021-02-27 06:33:13 [INFO] : --------------------------------------------
2021-02-27 06:33:13 [INFO] : ++++++++++++++++++++++++++++++++++++++++++++
2021-02-27 06:33:13 [INFO] : 正在获取 [绿盟] 威胁情报...
2021-02-27 06:33:14 [INFO] : 得到 [绿盟] 最新威胁情报 [0] 条
2021-02-27 06:33:14 [INFO] : --------------------------------------------
2021-02-27 06:33:14 [INFO] : ++++++++++++++++++++++++++++++++++++++++++++
2021-02-27 06:33:14 [INFO] : 正在获取 [奇安信] 威胁情报...
2021-02-27 06:33:16 [INFO] : 得到 [奇安信] 最新威胁情报 [0] 条
2021-02-27 06:33:16 [INFO] : --------------------------------------------
2021-02-27 06:33:16 [INFO] : ++++++++++++++++++++++++++++++++++++++++++++
2021-02-27 06:33:16 [INFO] : 正在获取 [红后] 威胁情报...
2021-02-27 06:33:18 [INFO] : 得到 [红后] 最新威胁情报 [0] 条
2021-02-27 06:33:18 [INFO] : --------------------------------------------
2021-02-27 06:33:18 [INFO] : ++++++++++++++++++++++++++++++++++++++++++++
2021-02-27 06:33:18 [INFO] : 正在获取 [安全客] 威胁情报...
2021-02-27 06:33:22 [INFO] : 得到 [安全客] 最新威胁情报 [0] 条
2021-02-27 06:33:22 [INFO] : --------------------------------------------
2021-02-27 06:33:22 [INFO] : ++++++++++++++++++++++++++++++++++++++++++++
2021-02-27 06:33:22 [INFO] : 正在获取 [斗象] 威胁情报...
2021-02-27 06:33:30 [INFO] : 得到 [斗象] 最新威胁情报 [0] 条
2021-02-27 06:33:30 [INFO] : --------------------------------------------
2021-02-27 06:33:30 [INFO] : ++++++++++++++++++++++++++++++++++++++++++++
2021-02-27 06:33:30 [INFO] : 正在获取 [CNVD] 威胁情报...
2021-02-27 06:33:33 [WARNING] : 获取 [CNVD] 威胁情报失败： [HTTP Error 521]
2021-02-27 06:33:33 [INFO] : 得到 [CNVD] 最新威胁情报 [0] 条
2021-02-27 06:33:33 [INFO] : --------------------------------------------
2021-02-27 07:28:32 [INFO] : ++++++++++++++++++++++++++++++++++++++++++++
2021-02-27 07:28:32 [INFO] : 正在获取 [360] 威胁情报...
2021-02-27 07:28:35 [INFO] : 得到 [360] 最新威胁情报 [0] 条
2021-02-27 07:28:35 [INFO] : --------------------------------------------
2021-02-27 07:28:35 [INFO] : ++++++++++++++++++++++++++++++++++++++++++++
2021-02-27 07:28:35 [INFO] : 正在获取 [绿盟] 威胁情报...
2021-02-27 07:28:36 [INFO] : 得到 [绿盟] 最新威胁情报 [0] 条
2021-02-27 07:28:36 [INFO] : --------------------------------------------
2021-02-27 07:28:36 [INFO] : ++++++++++++++++++++++++++++++++++++++++++++
2021-02-27 07:28:36 [INFO] : 正在获取 [奇安信] 威胁情报...
2021-02-27 07:28:40 [INFO] : 得到 [奇安信] 最新威胁情报 [0] 条
2021-02-27 07:28:40 [INFO] : --------------------------------------------
2021-02-27 07:28:40 [INFO] : ++++++++++++++++++++++++++++++++++++++++++++
2021-02-27 07:28:40 [INFO] : 正在获取 [红后] 威胁情报...
2021-02-27 07:28:46 [INFO] : 得到 [红后] 最新威胁情报 [0] 条
2021-02-27 07:28:46 [INFO] : --------------------------------------------
2021-02-27 07:28:46 [INFO] : ++++++++++++++++++++++++++++++++++++++++++++
2021-02-27 07:28:46 [INFO] : 正在获取 [安全客] 威胁情报...
2021-02-27 07:28:50 [INFO] : 得到 [安全客] 最新威胁情报 [0] 条
2021-02-27 07:28:50 [INFO] : --------------------------------------------
2021-02-27 07:28:50 [INFO] : ++++++++++++++++++++++++++++++++++++++++++++
2021-02-27 07:28:50 [INFO] : 正在获取 [斗象] 威胁情报...
2021-02-27 07:28:59 [INFO] : 得到 [斗象] 最新威胁情报 [0] 条
2021-02-27 07:28:59 [INFO] : --------------------------------------------
2021-02-27 07:28:59 [INFO] : ++++++++++++++++++++++++++++++++++++++++++++
2021-02-27 07:28:59 [INFO] : 正在获取 [CNVD] 威胁情报...
2021-02-27 07:29:02 [WARNING] : 获取 [CNVD] 威胁情报失败： [HTTP Error 521]
2021-02-27 07:29:02 [INFO] : 得到 [CNVD] 最新威胁情报 [0] 条
2021-02-27 07:29:02 [INFO] : --------------------------------------------
2021-02-27 08:34:05 [INFO] : ++++++++++++++++++++++++++++++++++++++++++++
2021-02-27 08:34:05 [INFO] : 正在获取 [360] 威胁情报...
2021-02-27 08:34:10 [INFO] : 得到 [360] 最新威胁情报 [0] 条
2021-02-27 08:34:10 [INFO] : --------------------------------------------
2021-02-27 08:34:10 [INFO] : ++++++++++++++++++++++++++++++++++++++++++++
2021-02-27 08:34:10 [INFO] : 正在获取 [绿盟] 威胁情报...
2021-02-27 08:34:11 [INFO] : 得到 [绿盟] 最新威胁情报 [0] 条
2021-02-27 08:34:11 [INFO] : --------------------------------------------
2021-02-27 08:34:11 [INFO] : ++++++++++++++++++++++++++++++++++++++++++++
2021-02-27 08:34:11 [INFO] : 正在获取 [奇安信] 威胁情报...
2021-02-27 08:34:17 [INFO] : 得到 [奇安信] 最新威胁情报 [0] 条
2021-02-27 08:34:17 [INFO] : --------------------------------------------
2021-02-27 08:34:17 [INFO] : ++++++++++++++++++++++++++++++++++++++++++++
2021-02-27 08:34:17 [INFO] : 正在获取 [红后] 威胁情报...
2021-02-27 08:34:20 [INFO] : 得到 [红后] 最新威胁情报 [0] 条
2021-02-27 08:34:20 [INFO] : --------------------------------------------
2021-02-27 08:34:20 [INFO] : ++++++++++++++++++++++++++++++++++++++++++++
2021-02-27 08:34:20 [INFO] : 正在获取 [安全客] 威胁情报...
2021-02-27 08:34:24 [INFO] : 得到 [安全客] 最新威胁情报 [0] 条
2021-02-27 08:34:24 [INFO] : --------------------------------------------
2021-02-27 08:34:24 [INFO] : ++++++++++++++++++++++++++++++++++++++++++++
2021-02-27 08:34:24 [INFO] : 正在获取 [斗象] 威胁情报...
2021-02-27 08:34:33 [INFO] : 得到 [斗象] 最新威胁情报 [0] 条
2021-02-27 08:34:33 [INFO] : --------------------------------------------
2021-02-27 08:34:33 [INFO] : ++++++++++++++++++++++++++++++++++++++++++++
2021-02-27 08:34:33 [INFO] : 正在获取 [CNVD] 威胁情报...
2021-02-27 08:34:43 [WARNING] : 获取 [CNVD] 威胁情报失败： [HTTP Error 521]
2021-02-27 08:34:43 [INFO] : 得到 [CNVD] 最新威胁情报 [0] 条
2021-02-27 08:34:43 [INFO] : --------------------------------------------
2021-02-27 09:30:29 [INFO] : ++++++++++++++++++++++++++++++++++++++++++++
2021-02-27 09:30:29 [INFO] : 正在获取 [360] 威胁情报...
2021-02-27 09:30:37 [INFO] : 得到 [360] 最新威胁情报 [0] 条
2021-02-27 09:30:37 [INFO] : --------------------------------------------
2021-02-27 09:30:37 [INFO] : ++++++++++++++++++++++++++++++++++++++++++++
2021-02-27 09:30:37 [INFO] : 正在获取 [绿盟] 威胁情报...
2021-02-27 09:30:38 [INFO] : 得到 [绿盟] 最新威胁情报 [0] 条
2021-02-27 09:30:38 [INFO] : --------------------------------------------
2021-02-27 09:30:38 [INFO] : ++++++++++++++++++++++++++++++++++++++++++++
2021-02-27 09:30:38 [INFO] : 正在获取 [奇安信] 威胁情报...
2021-02-27 09:30:40 [INFO] : 得到 [奇安信] 最新威胁情报 [0] 条
2021-02-27 09:30:40 [INFO] : --------------------------------------------
2021-02-27 09:30:40 [INFO] : ++++++++++++++++++++++++++++++++++++++++++++
2021-02-27 09:30:40 [INFO] : 正在获取 [红后] 威胁情报...
2021-02-27 09:30:43 [INFO] : 得到 [红后] 最新威胁情报 [10] 条
2021-02-27 09:30:43 [INFO] : --------------------------------------------
2021-02-27 09:30:43 [INFO] : 
==============================================
[ TITLE ] Linux kernel 安全漏洞
[ TIME  ] 2021-02-27 13:30:00
[ CVE   ] CVE-2021-26934
[ SRC   ] 红后
[ URL   ] https://redqueen.tj-un.com/IntelDetails.html?id=e9b95d6c26a84df6a6336cfbfd2691e4
2021-02-27 09:30:43 [INFO] : 
==============================================
[ TITLE ] Xterm 输入验证错误漏洞
[ TIME  ] 2021-02-27 13:30:00
[ CVE   ] CVE-2021-27135
[ SRC   ] 红后
[ URL   ] https://redqueen.tj-un.com/IntelDetails.html?id=a0f5aab5a16e493abd511cfe0a8502d6
2021-02-27 09:30:43 [INFO] : 
==============================================
[ TITLE ] ZOHOCORP MANAGEENGINE_ADSELFSERVICE_PLUS Vulnerability
[ TIME  ] 2021-02-27 13:30:00
[ CVE   ] CVE-2021-27214
[ SRC   ] 红后
[ URL   ] https://redqueen.tj-un.com/IntelDetails.html?id=7b8a7a5a50c2412f8390272ecb92301c
2021-02-27 09:30:43 [INFO] : 
==============================================
[ TITLE ] OpenLDAP 其他漏洞
[ TIME  ] 2021-02-27 13:29:58
[ CVE   ] CVE-2021-27212
[ SRC   ] 红后
[ URL   ] https://redqueen.tj-un.com/IntelDetails.html?id=ee53c92a3f6c4cfc801873afe3117586
2021-02-27 09:30:43 [INFO] : 
==============================================
[ TITLE ] LINUX LINUX_KERNEL Vulnerability
[ TIME  ] 2021-02-27 13:29:58
[ CVE   ] CVE-2021-26932
[ SRC   ] 红后
[ URL   ] https://redqueen.tj-un.com/IntelDetails.html?id=e607c7dc9507463f8405d6c3a0086667
2021-02-27 09:30:43 [INFO] : 
==============================================
[ TITLE ] DENX U-BOOT Vulnerability
[ TIME  ] 2021-02-27 13:29:58
[ CVE   ] CVE-2021-27097
[ SRC   ] 红后
[ URL   ] https://redqueen.tj-un.com/IntelDetails.html?id=4087ea244a344fd79fdf05232d2c8fca
2021-02-27 09:30:43 [INFO] : 
==============================================
[ TITLE ] DIGIUM Multiple product Vulnerability
[ TIME  ] 2021-02-27 13:29:36
[ CVE   ] CVE-2021-26713
[ SRC   ] 红后
[ URL   ] https://redqueen.tj-un.com/IntelDetails.html?id=d7dfbca69a97467da32ad951b92fd768
2021-02-27 09:30:43 [INFO] : 
==============================================
[ TITLE ] LINUX LINUX_KERNEL Vulnerability
[ TIME  ] 2021-02-27 13:29:36
[ CVE   ] CVE-2021-26931
[ SRC   ] 红后
[ URL   ] https://redqueen.tj-un.com/IntelDetails.html?id=ae444d9353cf436a9760ac49fd149c6d
2021-02-27 09:30:43 [INFO] : 
==============================================
[ TITLE ] DENX U-BOOT Vulnerability
[ TIME  ] 2021-02-27 13:29:36
[ CVE   ] CVE-2021-27138
[ SRC   ] 红后
[ URL   ] https://redqueen.tj-un.com/IntelDetails.html?id=9b4805f8123646039b5d1c8290ed629d
2021-02-27 09:30:43 [INFO] : 
==============================================
[ TITLE ] GNU Screen 参数注入漏洞
[ TIME  ] 2021-02-27 13:29:36
[ CVE   ] CVE-2021-26937
[ SRC   ] 红后
[ URL   ] https://redqueen.tj-un.com/IntelDetails.html?id=4ff6054a89144113ab71294cfca48416
2021-02-27 09:30:43 [INFO] : ++++++++++++++++++++++++++++++++++++++++++++
2021-02-27 09:30:43 [INFO] : 正在获取 [安全客] 威胁情报...
2021-02-27 09:30:46 [INFO] : 得到 [安全客] 最新威胁情报 [0] 条
2021-02-27 09:30:46 [INFO] : --------------------------------------------
2021-02-27 09:30:46 [INFO] : ++++++++++++++++++++++++++++++++++++++++++++
2021-02-27 09:30:46 [INFO] : 正在获取 [斗象] 威胁情报...
2021-02-27 09:30:55 [INFO] : 得到 [斗象] 最新威胁情报 [0] 条
2021-02-27 09:30:55 [INFO] : --------------------------------------------
2021-02-27 09:30:55 [INFO] : ++++++++++++++++++++++++++++++++++++++++++++
2021-02-27 09:30:55 [INFO] : 正在获取 [CNVD] 威胁情报...
2021-02-27 09:30:57 [WARNING] : 获取 [CNVD] 威胁情报失败： [HTTP Error 521]
2021-02-27 09:30:57 [INFO] : 得到 [CNVD] 最新威胁情报 [0] 条
2021-02-27 09:30:57 [INFO] : --------------------------------------------
2021-02-27 09:30:57 [INFO] : [邮件] 正在推送威胁情报...
2021-02-27 09:30:57 [INFO] : [邮件] 收件人清单： ['mrxn.net@gmail.com']
2021-02-27 09:31:02 [ERROR] : [邮件] 推送威胁情报失败
Traceback (most recent call last):
  File "/home/runner/work/threat-broadcast/threat-broadcast/src/notice/mail.py", line 47, in to_mail
    smtpObj.login(sender, password)
  File "/opt/hostedtoolcache/Python/3.8.7/x64/lib/python3.8/smtplib.py", line 732, in login
    raise last_exception
  File "/opt/hostedtoolcache/Python/3.8.7/x64/lib/python3.8/smtplib.py", line 721, in login
    (code, resp) = self.auth(
  File "/opt/hostedtoolcache/Python/3.8.7/x64/lib/python3.8/smtplib.py", line 644, in auth
    raise SMTPAuthenticationError(code, resp)
smtplib.SMTPAuthenticationError: (502, b'Invalid input from 100.107.4.130 to newxmesmtplogicsvrszc6.qq.com')
2021-02-27 09:31:02 [ERROR] : Traceback (most recent call last):
  File "/home/runner/work/threat-broadcast/threat-broadcast/src/notice/mail.py", line 47, in to_mail
    smtpObj.login(sender, password)
  File "/opt/hostedtoolcache/Python/3.8.7/x64/lib/python3.8/smtplib.py", line 732, in login
    raise last_exception
  File "/opt/hostedtoolcache/Python/3.8.7/x64/lib/python3.8/smtplib.py", line 721, in login
    (code, resp) = self.auth(
  File "/opt/hostedtoolcache/Python/3.8.7/x64/lib/python3.8/smtplib.py", line 644, in auth
    raise SMTPAuthenticationError(code, resp)
smtplib.SMTPAuthenticationError: (502, b'Invalid input from 100.107.4.130 to newxmesmtplogicsvrszc6.qq.com')
Traceback (most recent call last):
  File "/home/runner/work/threat-broadcast/threat-broadcast/src/notice/mail.py", line 47, in to_mail
    smtpObj.login(sender, password)
  File "/opt/hostedtoolcache/Python/3.8.7/x64/lib/python3.8/smtplib.py", line 732, in login
    raise last_exception
  File "/opt/hostedtoolcache/Python/3.8.7/x64/lib/python3.8/smtplib.py", line 721, in login
    (code, resp) = self.auth(
  File "/opt/hostedtoolcache/Python/3.8.7/x64/lib/python3.8/smtplib.py", line 644, in auth
    raise SMTPAuthenticationError(code, resp)
smtplib.SMTPAuthenticationError: (502, b'Invalid input from 100.107.4.130 to newxmesmtplogicsvrszc6.qq.com')
2021-02-27 10:32:15 [INFO] : ++++++++++++++++++++++++++++++++++++++++++++
2021-02-27 10:32:15 [INFO] : 正在获取 [360] 威胁情报...
2021-02-27 10:32:15 [INFO] : 得到 [360] 最新威胁情报 [0] 条
2021-02-27 10:32:15 [INFO] : --------------------------------------------
2021-02-27 10:32:15 [INFO] : ++++++++++++++++++++++++++++++++++++++++++++
2021-02-27 10:32:15 [INFO] : 正在获取 [绿盟] 威胁情报...
2021-02-27 10:32:16 [INFO] : 得到 [绿盟] 最新威胁情报 [0] 条
2021-02-27 10:32:16 [INFO] : --------------------------------------------
2021-02-27 10:32:16 [INFO] : ++++++++++++++++++++++++++++++++++++++++++++
2021-02-27 10:32:16 [INFO] : 正在获取 [奇安信] 威胁情报...
2021-02-27 10:32:18 [INFO] : 得到 [奇安信] 最新威胁情报 [0] 条
2021-02-27 10:32:18 [INFO] : --------------------------------------------
2021-02-27 10:32:18 [INFO] : ++++++++++++++++++++++++++++++++++++++++++++
2021-02-27 10:32:18 [INFO] : 正在获取 [红后] 威胁情报...
2021-02-27 10:32:20 [INFO] : 得到 [红后] 最新威胁情报 [0] 条
2021-02-27 10:32:20 [INFO] : --------------------------------------------
2021-02-27 10:32:20 [INFO] : ++++++++++++++++++++++++++++++++++++++++++++
2021-02-27 10:32:20 [INFO] : 正在获取 [安全客] 威胁情报...
2021-02-27 10:32:23 [INFO] : 得到 [安全客] 最新威胁情报 [0] 条
2021-02-27 10:32:23 [INFO] : --------------------------------------------
2021-02-27 10:32:23 [INFO] : ++++++++++++++++++++++++++++++++++++++++++++
2021-02-27 10:32:23 [INFO] : 正在获取 [斗象] 威胁情报...
2021-02-27 10:32:29 [INFO] : 得到 [斗象] 最新威胁情报 [0] 条
2021-02-27 10:32:29 [INFO] : --------------------------------------------
2021-02-27 10:32:29 [INFO] : ++++++++++++++++++++++++++++++++++++++++++++
2021-02-27 10:32:29 [INFO] : 正在获取 [CNVD] 威胁情报...
2021-02-27 10:32:31 [WARNING] : 获取 [CNVD] 威胁情报失败： [HTTP Error 521]
2021-02-27 10:32:31 [INFO] : 得到 [CNVD] 最新威胁情报 [0] 条
2021-02-27 10:32:31 [INFO] : --------------------------------------------
2021-02-27 11:27:11 [INFO] : ++++++++++++++++++++++++++++++++++++++++++++
2021-02-27 11:27:11 [INFO] : 正在获取 [360] 威胁情报...
2021-02-27 11:27:15 [INFO] : 得到 [360] 最新威胁情报 [0] 条
2021-02-27 11:27:15 [INFO] : --------------------------------------------
2021-02-27 11:27:15 [INFO] : ++++++++++++++++++++++++++++++++++++++++++++
2021-02-27 11:27:15 [INFO] : 正在获取 [绿盟] 威胁情报...
2021-02-27 11:27:16 [INFO] : 得到 [绿盟] 最新威胁情报 [0] 条
2021-02-27 11:27:16 [INFO] : --------------------------------------------
2021-02-27 11:27:16 [INFO] : ++++++++++++++++++++++++++++++++++++++++++++
2021-02-27 11:27:16 [INFO] : 正在获取 [奇安信] 威胁情报...
2021-02-27 11:27:18 [INFO] : 得到 [奇安信] 最新威胁情报 [0] 条
2021-02-27 11:27:18 [INFO] : --------------------------------------------
2021-02-27 11:27:18 [INFO] : ++++++++++++++++++++++++++++++++++++++++++++
2021-02-27 11:27:18 [INFO] : 正在获取 [红后] 威胁情报...
2021-02-27 11:27:21 [INFO] : 得到 [红后] 最新威胁情报 [0] 条
2021-02-27 11:27:21 [INFO] : --------------------------------------------
2021-02-27 11:27:21 [INFO] : ++++++++++++++++++++++++++++++++++++++++++++
2021-02-27 11:27:21 [INFO] : 正在获取 [安全客] 威胁情报...
2021-02-27 11:27:23 [INFO] : 得到 [安全客] 最新威胁情报 [0] 条
2021-02-27 11:27:23 [INFO] : --------------------------------------------
2021-02-27 11:27:23 [INFO] : ++++++++++++++++++++++++++++++++++++++++++++
2021-02-27 11:27:23 [INFO] : 正在获取 [斗象] 威胁情报...
2021-02-27 11:27:31 [INFO] : 得到 [斗象] 最新威胁情报 [0] 条
2021-02-27 11:27:31 [INFO] : --------------------------------------------
2021-02-27 11:27:31 [INFO] : ++++++++++++++++++++++++++++++++++++++++++++
2021-02-27 11:27:31 [INFO] : 正在获取 [CNVD] 威胁情报...
2021-02-27 11:27:33 [WARNING] : 获取 [CNVD] 威胁情报失败： [HTTP Error 521]
2021-02-27 11:27:33 [INFO] : 得到 [CNVD] 最新威胁情报 [0] 条
2021-02-27 11:27:33 [INFO] : --------------------------------------------
2021-02-27 12:39:41 [INFO] : ++++++++++++++++++++++++++++++++++++++++++++
2021-02-27 12:39:41 [INFO] : 正在获取 [360] 威胁情报...
2021-02-27 12:39:43 [INFO] : 得到 [360] 最新威胁情报 [0] 条
2021-02-27 12:39:43 [INFO] : --------------------------------------------
2021-02-27 12:39:43 [INFO] : ++++++++++++++++++++++++++++++++++++++++++++
2021-02-27 12:39:43 [INFO] : 正在获取 [绿盟] 威胁情报...
2021-02-27 12:39:44 [INFO] : 得到 [绿盟] 最新威胁情报 [0] 条
2021-02-27 12:39:44 [INFO] : --------------------------------------------
2021-02-27 12:39:44 [INFO] : ++++++++++++++++++++++++++++++++++++++++++++
2021-02-27 12:39:44 [INFO] : 正在获取 [奇安信] 威胁情报...
2021-02-27 12:39:47 [INFO] : 得到 [奇安信] 最新威胁情报 [0] 条
2021-02-27 12:39:47 [INFO] : --------------------------------------------
2021-02-27 12:39:47 [INFO] : ++++++++++++++++++++++++++++++++++++++++++++
2021-02-27 12:39:47 [INFO] : 正在获取 [红后] 威胁情报...
2021-02-27 12:39:51 [INFO] : 得到 [红后] 最新威胁情报 [0] 条
2021-02-27 12:39:51 [INFO] : --------------------------------------------
2021-02-27 12:39:51 [INFO] : ++++++++++++++++++++++++++++++++++++++++++++
2021-02-27 12:39:51 [INFO] : 正在获取 [安全客] 威胁情报...
2021-02-27 12:40:53 [ERROR] : 获取 [安全客] 威胁情报异常
Traceback (most recent call last):
  File "/opt/hostedtoolcache/Python/3.8.7/x64/lib/python3.8/site-packages/urllib3/connectionpool.py", line 381, in _make_request
    self._validate_conn(conn)
  File "/opt/hostedtoolcache/Python/3.8.7/x64/lib/python3.8/site-packages/urllib3/connectionpool.py", line 978, in _validate_conn
    conn.connect()
  File "/opt/hostedtoolcache/Python/3.8.7/x64/lib/python3.8/site-packages/urllib3/connection.py", line 362, in connect
    self.sock = ssl_wrap_socket(
  File "/opt/hostedtoolcache/Python/3.8.7/x64/lib/python3.8/site-packages/urllib3/util/ssl_.py", line 386, in ssl_wrap_socket
    return context.wrap_socket(sock, server_hostname=server_hostname)
  File "/opt/hostedtoolcache/Python/3.8.7/x64/lib/python3.8/ssl.py", line 500, in wrap_socket
    return self.sslsocket_class._create(
  File "/opt/hostedtoolcache/Python/3.8.7/x64/lib/python3.8/ssl.py", line 1040, in _create
    self.do_handshake()
  File "/opt/hostedtoolcache/Python/3.8.7/x64/lib/python3.8/ssl.py", line 1309, in do_handshake
    self._sslobj.do_handshake()
socket.timeout: _ssl.c:1108: The handshake operation timed out

During handling of the above exception, another exception occurred:

Traceback (most recent call last):
  File "/opt/hostedtoolcache/Python/3.8.7/x64/lib/python3.8/site-packages/requests/adapters.py", line 439, in send
    resp = conn.urlopen(
  File "/opt/hostedtoolcache/Python/3.8.7/x64/lib/python3.8/site-packages/urllib3/connectionpool.py", line 726, in urlopen
    retries = retries.increment(
  File "/opt/hostedtoolcache/Python/3.8.7/x64/lib/python3.8/site-packages/urllib3/util/retry.py", line 410, in increment
    raise six.reraise(type(error), error, _stacktrace)
  File "/opt/hostedtoolcache/Python/3.8.7/x64/lib/python3.8/site-packages/urllib3/packages/six.py", line 735, in reraise
    raise value
  File "/opt/hostedtoolcache/Python/3.8.7/x64/lib/python3.8/site-packages/urllib3/connectionpool.py", line 670, in urlopen
    httplib_response = self._make_request(
  File "/opt/hostedtoolcache/Python/3.8.7/x64/lib/python3.8/site-packages/urllib3/connectionpool.py", line 384, in _make_request
    self._raise_timeout(err=e, url=url, timeout_value=conn.timeout)
  File "/opt/hostedtoolcache/Python/3.8.7/x64/lib/python3.8/site-packages/urllib3/connectionpool.py", line 335, in _raise_timeout
    raise ReadTimeoutError(
urllib3.exceptions.ReadTimeoutError: HTTPSConnectionPool(host='www.anquanke.com', port=443): Read timed out. (read timeout=60)

During handling of the above exception, another exception occurred:

Traceback (most recent call last):
  File "/home/runner/work/threat-broadcast/threat-broadcast/src/crawler/_base_crawler.py", line 62, in cves
    new_cves = self.get_cves()
  File "/home/runner/work/threat-broadcast/threat-broadcast/src/crawler/anquanke.py", line 41, in get_cves
    response = requests.get(
  File "/opt/hostedtoolcache/Python/3.8.7/x64/lib/python3.8/site-packages/requests/api.py", line 75, in get
    return request('get', url, params=params, **kwargs)
  File "/opt/hostedtoolcache/Python/3.8.7/x64/lib/python3.8/site-packages/requests/api.py", line 60, in request
    return session.request(method=method, url=url, **kwargs)
  File "/opt/hostedtoolcache/Python/3.8.7/x64/lib/python3.8/site-packages/requests/sessions.py", line 533, in request
    resp = self.send(prep, **send_kwargs)
  File "/opt/hostedtoolcache/Python/3.8.7/x64/lib/python3.8/site-packages/requests/sessions.py", line 646, in send
    r = adapter.send(request, **kwargs)
  File "/opt/hostedtoolcache/Python/3.8.7/x64/lib/python3.8/site-packages/requests/adapters.py", line 529, in send
    raise ReadTimeout(e, request=request)
requests.exceptions.ReadTimeout: HTTPSConnectionPool(host='www.anquanke.com', port=443): Read timed out. (read timeout=60)
2021-02-27 12:40:53 [ERROR] : Traceback (most recent call last):
  File "/opt/hostedtoolcache/Python/3.8.7/x64/lib/python3.8/site-packages/urllib3/connectionpool.py", line 381, in _make_request
    self._validate_conn(conn)
  File "/opt/hostedtoolcache/Python/3.8.7/x64/lib/python3.8/site-packages/urllib3/connectionpool.py", line 978, in _validate_conn
    conn.connect()
  File "/opt/hostedtoolcache/Python/3.8.7/x64/lib/python3.8/site-packages/urllib3/connection.py", line 362, in connect
    self.sock = ssl_wrap_socket(
  File "/opt/hostedtoolcache/Python/3.8.7/x64/lib/python3.8/site-packages/urllib3/util/ssl_.py", line 386, in ssl_wrap_socket
    return context.wrap_socket(sock, server_hostname=server_hostname)
  File "/opt/hostedtoolcache/Python/3.8.7/x64/lib/python3.8/ssl.py", line 500, in wrap_socket
    return self.sslsocket_class._create(
  File "/opt/hostedtoolcache/Python/3.8.7/x64/lib/python3.8/ssl.py", line 1040, in _create
    self.do_handshake()
  File "/opt/hostedtoolcache/Python/3.8.7/x64/lib/python3.8/ssl.py", line 1309, in do_handshake
    self._sslobj.do_handshake()
socket.timeout: _ssl.c:1108: The handshake operation timed out

During handling of the above exception, another exception occurred:

Traceback (most recent call last):
  File "/opt/hostedtoolcache/Python/3.8.7/x64/lib/python3.8/site-packages/requests/adapters.py", line 439, in send
    resp = conn.urlopen(
  File "/opt/hostedtoolcache/Python/3.8.7/x64/lib/python3.8/site-packages/urllib3/connectionpool.py", line 726, in urlopen
    retries = retries.increment(
  File "/opt/hostedtoolcache/Python/3.8.7/x64/lib/python3.8/site-packages/urllib3/util/retry.py", line 410, in increment
    raise six.reraise(type(error), error, _stacktrace)
  File "/opt/hostedtoolcache/Python/3.8.7/x64/lib/python3.8/site-packages/urllib3/packages/six.py", line 735, in reraise
    raise value
  File "/opt/hostedtoolcache/Python/3.8.7/x64/lib/python3.8/site-packages/urllib3/connectionpool.py", line 670, in urlopen
    httplib_response = self._make_request(
  File "/opt/hostedtoolcache/Python/3.8.7/x64/lib/python3.8/site-packages/urllib3/connectionpool.py", line 384, in _make_request
    self._raise_timeout(err=e, url=url, timeout_value=conn.timeout)
  File "/opt/hostedtoolcache/Python/3.8.7/x64/lib/python3.8/site-packages/urllib3/connectionpool.py", line 335, in _raise_timeout
    raise ReadTimeoutError(
urllib3.exceptions.ReadTimeoutError: HTTPSConnectionPool(host='www.anquanke.com', port=443): Read timed out. (read timeout=60)

During handling of the above exception, another exception occurred:

Traceback (most recent call last):
  File "/home/runner/work/threat-broadcast/threat-broadcast/src/crawler/_base_crawler.py", line 62, in cves
    new_cves = self.get_cves()
  File "/home/runner/work/threat-broadcast/threat-broadcast/src/crawler/anquanke.py", line 41, in get_cves
    response = requests.get(
  File "/opt/hostedtoolcache/Python/3.8.7/x64/lib/python3.8/site-packages/requests/api.py", line 75, in get
    return request('get', url, params=params, **kwargs)
  File "/opt/hostedtoolcache/Python/3.8.7/x64/lib/python3.8/site-packages/requests/api.py", line 60, in request
    return session.request(method=method, url=url, **kwargs)
  File "/opt/hostedtoolcache/Python/3.8.7/x64/lib/python3.8/site-packages/requests/sessions.py", line 533, in request
    resp = self.send(prep, **send_kwargs)
  File "/opt/hostedtoolcache/Python/3.8.7/x64/lib/python3.8/site-packages/requests/sessions.py", line 646, in send
    r = adapter.send(request, **kwargs)
  File "/opt/hostedtoolcache/Python/3.8.7/x64/lib/python3.8/site-packages/requests/adapters.py", line 529, in send
    raise ReadTimeout(e, request=request)
requests.exceptions.ReadTimeout: HTTPSConnectionPool(host='www.anquanke.com', port=443): Read timed out. (read timeout=60)
Traceback (most recent call last):
  File "/opt/hostedtoolcache/Python/3.8.7/x64/lib/python3.8/site-packages/urllib3/connectionpool.py", line 381, in _make_request
    self._validate_conn(conn)
  File "/opt/hostedtoolcache/Python/3.8.7/x64/lib/python3.8/site-packages/urllib3/connectionpool.py", line 978, in _validate_conn
    conn.connect()
  File "/opt/hostedtoolcache/Python/3.8.7/x64/lib/python3.8/site-packages/urllib3/connection.py", line 362, in connect
    self.sock = ssl_wrap_socket(
  File "/opt/hostedtoolcache/Python/3.8.7/x64/lib/python3.8/site-packages/urllib3/util/ssl_.py", line 386, in ssl_wrap_socket
    return context.wrap_socket(sock, server_hostname=server_hostname)
  File "/opt/hostedtoolcache/Python/3.8.7/x64/lib/python3.8/ssl.py", line 500, in wrap_socket
    return self.sslsocket_class._create(
  File "/opt/hostedtoolcache/Python/3.8.7/x64/lib/python3.8/ssl.py", line 1040, in _create
    self.do_handshake()
  File "/opt/hostedtoolcache/Python/3.8.7/x64/lib/python3.8/ssl.py", line 1309, in do_handshake
    self._sslobj.do_handshake()
socket.timeout: _ssl.c:1108: The handshake operation timed out

During handling of the above exception, another exception occurred:

Traceback (most recent call last):
  File "/opt/hostedtoolcache/Python/3.8.7/x64/lib/python3.8/site-packages/requests/adapters.py", line 439, in send
    resp = conn.urlopen(
  File "/opt/hostedtoolcache/Python/3.8.7/x64/lib/python3.8/site-packages/urllib3/connectionpool.py", line 726, in urlopen
    retries = retries.increment(
  File "/opt/hostedtoolcache/Python/3.8.7/x64/lib/python3.8/site-packages/urllib3/util/retry.py", line 410, in increment
    raise six.reraise(type(error), error, _stacktrace)
  File "/opt/hostedtoolcache/Python/3.8.7/x64/lib/python3.8/site-packages/urllib3/packages/six.py", line 735, in reraise
    raise value
  File "/opt/hostedtoolcache/Python/3.8.7/x64/lib/python3.8/site-packages/urllib3/connectionpool.py", line 670, in urlopen
    httplib_response = self._make_request(
  File "/opt/hostedtoolcache/Python/3.8.7/x64/lib/python3.8/site-packages/urllib3/connectionpool.py", line 384, in _make_request
    self._raise_timeout(err=e, url=url, timeout_value=conn.timeout)
  File "/opt/hostedtoolcache/Python/3.8.7/x64/lib/python3.8/site-packages/urllib3/connectionpool.py", line 335, in _raise_timeout
    raise ReadTimeoutError(
urllib3.exceptions.ReadTimeoutError: HTTPSConnectionPool(host='www.anquanke.com', port=443): Read timed out. (read timeout=60)

During handling of the above exception, another exception occurred:

Traceback (most recent call last):
  File "/home/runner/work/threat-broadcast/threat-broadcast/src/crawler/_base_crawler.py", line 62, in cves
    new_cves = self.get_cves()
  File "/home/runner/work/threat-broadcast/threat-broadcast/src/crawler/anquanke.py", line 41, in get_cves
    response = requests.get(
  File "/opt/hostedtoolcache/Python/3.8.7/x64/lib/python3.8/site-packages/requests/api.py", line 75, in get
    return request('get', url, params=params, **kwargs)
  File "/opt/hostedtoolcache/Python/3.8.7/x64/lib/python3.8/site-packages/requests/api.py", line 60, in request
    return session.request(method=method, url=url, **kwargs)
  File "/opt/hostedtoolcache/Python/3.8.7/x64/lib/python3.8/site-packages/requests/sessions.py", line 533, in request
    resp = self.send(prep, **send_kwargs)
  File "/opt/hostedtoolcache/Python/3.8.7/x64/lib/python3.8/site-packages/requests/sessions.py", line 646, in send
    r = adapter.send(request, **kwargs)
  File "/opt/hostedtoolcache/Python/3.8.7/x64/lib/python3.8/site-packages/requests/adapters.py", line 529, in send
    raise ReadTimeout(e, request=request)
requests.exceptions.ReadTimeout: HTTPSConnectionPool(host='www.anquanke.com', port=443): Read timed out. (read timeout=60)
2021-02-27 12:40:53 [INFO] : 得到 [安全客] 最新威胁情报 [0] 条
2021-02-27 12:40:53 [INFO] : --------------------------------------------
2021-02-27 12:40:53 [INFO] : ++++++++++++++++++++++++++++++++++++++++++++
2021-02-27 12:40:53 [INFO] : 正在获取 [斗象] 威胁情报...
2021-02-27 12:41:02 [INFO] : 得到 [斗象] 最新威胁情报 [0] 条
2021-02-27 12:41:02 [INFO] : --------------------------------------------
2021-02-27 12:41:02 [INFO] : ++++++++++++++++++++++++++++++++++++++++++++
2021-02-27 12:41:02 [INFO] : 正在获取 [CNVD] 威胁情报...
2021-02-27 12:41:05 [WARNING] : 获取 [CNVD] 威胁情报失败： [HTTP Error 521]
2021-02-27 12:41:05 [INFO] : 得到 [CNVD] 最新威胁情报 [0] 条
2021-02-27 12:41:05 [INFO] : --------------------------------------------
2021-02-27 13:27:51 [INFO] : ++++++++++++++++++++++++++++++++++++++++++++
2021-02-27 13:27:51 [INFO] : 正在获取 [360] 威胁情报...
2021-02-27 13:28:01 [INFO] : 得到 [360] 最新威胁情报 [0] 条
2021-02-27 13:28:01 [INFO] : --------------------------------------------
2021-02-27 13:28:01 [INFO] : ++++++++++++++++++++++++++++++++++++++++++++
2021-02-27 13:28:01 [INFO] : 正在获取 [绿盟] 威胁情报...
2021-02-27 13:28:02 [INFO] : 得到 [绿盟] 最新威胁情报 [0] 条
2021-02-27 13:28:02 [INFO] : --------------------------------------------
2021-02-27 13:28:02 [INFO] : ++++++++++++++++++++++++++++++++++++++++++++
2021-02-27 13:28:02 [INFO] : 正在获取 [奇安信] 威胁情报...
2021-02-27 13:28:04 [INFO] : 得到 [奇安信] 最新威胁情报 [0] 条
2021-02-27 13:28:04 [INFO] : --------------------------------------------
2021-02-27 13:28:04 [INFO] : ++++++++++++++++++++++++++++++++++++++++++++
2021-02-27 13:28:04 [INFO] : 正在获取 [红后] 威胁情报...
2021-02-27 13:28:07 [INFO] : 得到 [红后] 最新威胁情报 [0] 条
2021-02-27 13:28:07 [INFO] : --------------------------------------------
2021-02-27 13:28:07 [INFO] : ++++++++++++++++++++++++++++++++++++++++++++
2021-02-27 13:28:07 [INFO] : 正在获取 [安全客] 威胁情报...
2021-02-27 13:29:08 [ERROR] : 获取 [安全客] 威胁情报异常
Traceback (most recent call last):
  File "/opt/hostedtoolcache/Python/3.8.7/x64/lib/python3.8/site-packages/urllib3/connectionpool.py", line 381, in _make_request
    self._validate_conn(conn)
  File "/opt/hostedtoolcache/Python/3.8.7/x64/lib/python3.8/site-packages/urllib3/connectionpool.py", line 978, in _validate_conn
    conn.connect()
  File "/opt/hostedtoolcache/Python/3.8.7/x64/lib/python3.8/site-packages/urllib3/connection.py", line 362, in connect
    self.sock = ssl_wrap_socket(
  File "/opt/hostedtoolcache/Python/3.8.7/x64/lib/python3.8/site-packages/urllib3/util/ssl_.py", line 386, in ssl_wrap_socket
    return context.wrap_socket(sock, server_hostname=server_hostname)
  File "/opt/hostedtoolcache/Python/3.8.7/x64/lib/python3.8/ssl.py", line 500, in wrap_socket
    return self.sslsocket_class._create(
  File "/opt/hostedtoolcache/Python/3.8.7/x64/lib/python3.8/ssl.py", line 1040, in _create
    self.do_handshake()
  File "/opt/hostedtoolcache/Python/3.8.7/x64/lib/python3.8/ssl.py", line 1309, in do_handshake
    self._sslobj.do_handshake()
socket.timeout: _ssl.c:1108: The handshake operation timed out

During handling of the above exception, another exception occurred:

Traceback (most recent call last):
  File "/opt/hostedtoolcache/Python/3.8.7/x64/lib/python3.8/site-packages/requests/adapters.py", line 439, in send
    resp = conn.urlopen(
  File "/opt/hostedtoolcache/Python/3.8.7/x64/lib/python3.8/site-packages/urllib3/connectionpool.py", line 726, in urlopen
    retries = retries.increment(
  File "/opt/hostedtoolcache/Python/3.8.7/x64/lib/python3.8/site-packages/urllib3/util/retry.py", line 410, in increment
    raise six.reraise(type(error), error, _stacktrace)
  File "/opt/hostedtoolcache/Python/3.8.7/x64/lib/python3.8/site-packages/urllib3/packages/six.py", line 735, in reraise
    raise value
  File "/opt/hostedtoolcache/Python/3.8.7/x64/lib/python3.8/site-packages/urllib3/connectionpool.py", line 670, in urlopen
    httplib_response = self._make_request(
  File "/opt/hostedtoolcache/Python/3.8.7/x64/lib/python3.8/site-packages/urllib3/connectionpool.py", line 384, in _make_request
    self._raise_timeout(err=e, url=url, timeout_value=conn.timeout)
  File "/opt/hostedtoolcache/Python/3.8.7/x64/lib/python3.8/site-packages/urllib3/connectionpool.py", line 335, in _raise_timeout
    raise ReadTimeoutError(
urllib3.exceptions.ReadTimeoutError: HTTPSConnectionPool(host='www.anquanke.com', port=443): Read timed out. (read timeout=60)

During handling of the above exception, another exception occurred:

Traceback (most recent call last):
  File "/home/runner/work/threat-broadcast/threat-broadcast/src/crawler/_base_crawler.py", line 62, in cves
    new_cves = self.get_cves()
  File "/home/runner/work/threat-broadcast/threat-broadcast/src/crawler/anquanke.py", line 41, in get_cves
    response = requests.get(
  File "/opt/hostedtoolcache/Python/3.8.7/x64/lib/python3.8/site-packages/requests/api.py", line 75, in get
    return request('get', url, params=params, **kwargs)
  File "/opt/hostedtoolcache/Python/3.8.7/x64/lib/python3.8/site-packages/requests/api.py", line 60, in request
    return session.request(method=method, url=url, **kwargs)
  File "/opt/hostedtoolcache/Python/3.8.7/x64/lib/python3.8/site-packages/requests/sessions.py", line 533, in request
    resp = self.send(prep, **send_kwargs)
  File "/opt/hostedtoolcache/Python/3.8.7/x64/lib/python3.8/site-packages/requests/sessions.py", line 646, in send
    r = adapter.send(request, **kwargs)
  File "/opt/hostedtoolcache/Python/3.8.7/x64/lib/python3.8/site-packages/requests/adapters.py", line 529, in send
    raise ReadTimeout(e, request=request)
requests.exceptions.ReadTimeout: HTTPSConnectionPool(host='www.anquanke.com', port=443): Read timed out. (read timeout=60)
2021-02-27 13:29:08 [ERROR] : Traceback (most recent call last):
  File "/opt/hostedtoolcache/Python/3.8.7/x64/lib/python3.8/site-packages/urllib3/connectionpool.py", line 381, in _make_request
    self._validate_conn(conn)
  File "/opt/hostedtoolcache/Python/3.8.7/x64/lib/python3.8/site-packages/urllib3/connectionpool.py", line 978, in _validate_conn
    conn.connect()
  File "/opt/hostedtoolcache/Python/3.8.7/x64/lib/python3.8/site-packages/urllib3/connection.py", line 362, in connect
    self.sock = ssl_wrap_socket(
  File "/opt/hostedtoolcache/Python/3.8.7/x64/lib/python3.8/site-packages/urllib3/util/ssl_.py", line 386, in ssl_wrap_socket
    return context.wrap_socket(sock, server_hostname=server_hostname)
  File "/opt/hostedtoolcache/Python/3.8.7/x64/lib/python3.8/ssl.py", line 500, in wrap_socket
    return self.sslsocket_class._create(
  File "/opt/hostedtoolcache/Python/3.8.7/x64/lib/python3.8/ssl.py", line 1040, in _create
    self.do_handshake()
  File "/opt/hostedtoolcache/Python/3.8.7/x64/lib/python3.8/ssl.py", line 1309, in do_handshake
    self._sslobj.do_handshake()
socket.timeout: _ssl.c:1108: The handshake operation timed out

During handling of the above exception, another exception occurred:

Traceback (most recent call last):
  File "/opt/hostedtoolcache/Python/3.8.7/x64/lib/python3.8/site-packages/requests/adapters.py", line 439, in send
    resp = conn.urlopen(
  File "/opt/hostedtoolcache/Python/3.8.7/x64/lib/python3.8/site-packages/urllib3/connectionpool.py", line 726, in urlopen
    retries = retries.increment(
  File "/opt/hostedtoolcache/Python/3.8.7/x64/lib/python3.8/site-packages/urllib3/util/retry.py", line 410, in increment
    raise six.reraise(type(error), error, _stacktrace)
  File "/opt/hostedtoolcache/Python/3.8.7/x64/lib/python3.8/site-packages/urllib3/packages/six.py", line 735, in reraise
    raise value
  File "/opt/hostedtoolcache/Python/3.8.7/x64/lib/python3.8/site-packages/urllib3/connectionpool.py", line 670, in urlopen
    httplib_response = self._make_request(
  File "/opt/hostedtoolcache/Python/3.8.7/x64/lib/python3.8/site-packages/urllib3/connectionpool.py", line 384, in _make_request
    self._raise_timeout(err=e, url=url, timeout_value=conn.timeout)
  File "/opt/hostedtoolcache/Python/3.8.7/x64/lib/python3.8/site-packages/urllib3/connectionpool.py", line 335, in _raise_timeout
    raise ReadTimeoutError(
urllib3.exceptions.ReadTimeoutError: HTTPSConnectionPool(host='www.anquanke.com', port=443): Read timed out. (read timeout=60)

During handling of the above exception, another exception occurred:

Traceback (most recent call last):
  File "/home/runner/work/threat-broadcast/threat-broadcast/src/crawler/_base_crawler.py", line 62, in cves
    new_cves = self.get_cves()
  File "/home/runner/work/threat-broadcast/threat-broadcast/src/crawler/anquanke.py", line 41, in get_cves
    response = requests.get(
  File "/opt/hostedtoolcache/Python/3.8.7/x64/lib/python3.8/site-packages/requests/api.py", line 75, in get
    return request('get', url, params=params, **kwargs)
  File "/opt/hostedtoolcache/Python/3.8.7/x64/lib/python3.8/site-packages/requests/api.py", line 60, in request
    return session.request(method=method, url=url, **kwargs)
  File "/opt/hostedtoolcache/Python/3.8.7/x64/lib/python3.8/site-packages/requests/sessions.py", line 533, in request
    resp = self.send(prep, **send_kwargs)
  File "/opt/hostedtoolcache/Python/3.8.7/x64/lib/python3.8/site-packages/requests/sessions.py", line 646, in send
    r = adapter.send(request, **kwargs)
  File "/opt/hostedtoolcache/Python/3.8.7/x64/lib/python3.8/site-packages/requests/adapters.py", line 529, in send
    raise ReadTimeout(e, request=request)
requests.exceptions.ReadTimeout: HTTPSConnectionPool(host='www.anquanke.com', port=443): Read timed out. (read timeout=60)
Traceback (most recent call last):
  File "/opt/hostedtoolcache/Python/3.8.7/x64/lib/python3.8/site-packages/urllib3/connectionpool.py", line 381, in _make_request
    self._validate_conn(conn)
  File "/opt/hostedtoolcache/Python/3.8.7/x64/lib/python3.8/site-packages/urllib3/connectionpool.py", line 978, in _validate_conn
    conn.connect()
  File "/opt/hostedtoolcache/Python/3.8.7/x64/lib/python3.8/site-packages/urllib3/connection.py", line 362, in connect
    self.sock = ssl_wrap_socket(
  File "/opt/hostedtoolcache/Python/3.8.7/x64/lib/python3.8/site-packages/urllib3/util/ssl_.py", line 386, in ssl_wrap_socket
    return context.wrap_socket(sock, server_hostname=server_hostname)
  File "/opt/hostedtoolcache/Python/3.8.7/x64/lib/python3.8/ssl.py", line 500, in wrap_socket
    return self.sslsocket_class._create(
  File "/opt/hostedtoolcache/Python/3.8.7/x64/lib/python3.8/ssl.py", line 1040, in _create
    self.do_handshake()
  File "/opt/hostedtoolcache/Python/3.8.7/x64/lib/python3.8/ssl.py", line 1309, in do_handshake
    self._sslobj.do_handshake()
socket.timeout: _ssl.c:1108: The handshake operation timed out

During handling of the above exception, another exception occurred:

Traceback (most recent call last):
  File "/opt/hostedtoolcache/Python/3.8.7/x64/lib/python3.8/site-packages/requests/adapters.py", line 439, in send
    resp = conn.urlopen(
  File "/opt/hostedtoolcache/Python/3.8.7/x64/lib/python3.8/site-packages/urllib3/connectionpool.py", line 726, in urlopen
    retries = retries.increment(
  File "/opt/hostedtoolcache/Python/3.8.7/x64/lib/python3.8/site-packages/urllib3/util/retry.py", line 410, in increment
    raise six.reraise(type(error), error, _stacktrace)
  File "/opt/hostedtoolcache/Python/3.8.7/x64/lib/python3.8/site-packages/urllib3/packages/six.py", line 735, in reraise
    raise value
  File "/opt/hostedtoolcache/Python/3.8.7/x64/lib/python3.8/site-packages/urllib3/connectionpool.py", line 670, in urlopen
    httplib_response = self._make_request(
  File "/opt/hostedtoolcache/Python/3.8.7/x64/lib/python3.8/site-packages/urllib3/connectionpool.py", line 384, in _make_request
    self._raise_timeout(err=e, url=url, timeout_value=conn.timeout)
  File "/opt/hostedtoolcache/Python/3.8.7/x64/lib/python3.8/site-packages/urllib3/connectionpool.py", line 335, in _raise_timeout
    raise ReadTimeoutError(
urllib3.exceptions.ReadTimeoutError: HTTPSConnectionPool(host='www.anquanke.com', port=443): Read timed out. (read timeout=60)

During handling of the above exception, another exception occurred:

Traceback (most recent call last):
  File "/home/runner/work/threat-broadcast/threat-broadcast/src/crawler/_base_crawler.py", line 62, in cves
    new_cves = self.get_cves()
  File "/home/runner/work/threat-broadcast/threat-broadcast/src/crawler/anquanke.py", line 41, in get_cves
    response = requests.get(
  File "/opt/hostedtoolcache/Python/3.8.7/x64/lib/python3.8/site-packages/requests/api.py", line 75, in get
    return request('get', url, params=params, **kwargs)
  File "/opt/hostedtoolcache/Python/3.8.7/x64/lib/python3.8/site-packages/requests/api.py", line 60, in request
    return session.request(method=method, url=url, **kwargs)
  File "/opt/hostedtoolcache/Python/3.8.7/x64/lib/python3.8/site-packages/requests/sessions.py", line 533, in request
    resp = self.send(prep, **send_kwargs)
  File "/opt/hostedtoolcache/Python/3.8.7/x64/lib/python3.8/site-packages/requests/sessions.py", line 646, in send
    r = adapter.send(request, **kwargs)
  File "/opt/hostedtoolcache/Python/3.8.7/x64/lib/python3.8/site-packages/requests/adapters.py", line 529, in send
    raise ReadTimeout(e, request=request)
requests.exceptions.ReadTimeout: HTTPSConnectionPool(host='www.anquanke.com', port=443): Read timed out. (read timeout=60)
2021-02-27 13:29:08 [INFO] : 得到 [安全客] 最新威胁情报 [0] 条
2021-02-27 13:29:08 [INFO] : --------------------------------------------
2021-02-27 13:29:08 [INFO] : ++++++++++++++++++++++++++++++++++++++++++++
2021-02-27 13:29:08 [INFO] : 正在获取 [斗象] 威胁情报...
2021-02-27 13:29:19 [INFO] : 得到 [斗象] 最新威胁情报 [0] 条
2021-02-27 13:29:19 [INFO] : --------------------------------------------
2021-02-27 13:29:19 [INFO] : ++++++++++++++++++++++++++++++++++++++++++++
2021-02-27 13:29:19 [INFO] : 正在获取 [CNVD] 威胁情报...
2021-02-27 13:29:26 [WARNING] : 获取 [CNVD] 威胁情报失败： [HTTP Error 521]
2021-02-27 13:29:26 [INFO] : 得到 [CNVD] 最新威胁情报 [0] 条
2021-02-27 13:29:26 [INFO] : --------------------------------------------
2021-02-27 14:27:33 [INFO] : ++++++++++++++++++++++++++++++++++++++++++++
2021-02-27 14:27:33 [INFO] : 正在获取 [360] 威胁情报...
2021-02-27 14:27:36 [INFO] : 得到 [360] 最新威胁情报 [0] 条
2021-02-27 14:27:36 [INFO] : --------------------------------------------
2021-02-27 14:27:36 [INFO] : ++++++++++++++++++++++++++++++++++++++++++++
2021-02-27 14:27:36 [INFO] : 正在获取 [绿盟] 威胁情报...
2021-02-27 14:27:37 [INFO] : 得到 [绿盟] 最新威胁情报 [0] 条
2021-02-27 14:27:37 [INFO] : --------------------------------------------
2021-02-27 14:27:37 [INFO] : ++++++++++++++++++++++++++++++++++++++++++++
2021-02-27 14:27:37 [INFO] : 正在获取 [奇安信] 威胁情报...
2021-02-27 14:27:40 [INFO] : 得到 [奇安信] 最新威胁情报 [0] 条
2021-02-27 14:27:40 [INFO] : --------------------------------------------
2021-02-27 14:27:40 [INFO] : ++++++++++++++++++++++++++++++++++++++++++++
2021-02-27 14:27:40 [INFO] : 正在获取 [红后] 威胁情报...
2021-02-27 14:27:43 [INFO] : 得到 [红后] 最新威胁情报 [0] 条
2021-02-27 14:27:43 [INFO] : --------------------------------------------
2021-02-27 14:27:43 [INFO] : ++++++++++++++++++++++++++++++++++++++++++++
2021-02-27 14:27:43 [INFO] : 正在获取 [安全客] 威胁情报...
2021-02-27 14:27:45 [INFO] : 得到 [安全客] 最新威胁情报 [0] 条
2021-02-27 14:27:45 [INFO] : --------------------------------------------
2021-02-27 14:27:45 [INFO] : ++++++++++++++++++++++++++++++++++++++++++++
2021-02-27 14:27:45 [INFO] : 正在获取 [斗象] 威胁情报...
2021-02-27 14:27:54 [INFO] : 得到 [斗象] 最新威胁情报 [0] 条
2021-02-27 14:27:54 [INFO] : --------------------------------------------
2021-02-27 14:27:54 [INFO] : ++++++++++++++++++++++++++++++++++++++++++++
2021-02-27 14:27:54 [INFO] : 正在获取 [CNVD] 威胁情报...
2021-02-27 14:27:59 [WARNING] : 获取 [CNVD] 威胁情报失败： [HTTP Error 521]
2021-02-27 14:27:59 [INFO] : 得到 [CNVD] 最新威胁情报 [0] 条
2021-02-27 14:27:59 [INFO] : --------------------------------------------
2021-02-27 15:29:28 [INFO] : ++++++++++++++++++++++++++++++++++++++++++++
2021-02-27 15:29:28 [INFO] : 正在获取 [360] 威胁情报...
2021-02-27 15:29:39 [ERROR] : 获取 [360] 威胁情报异常
Traceback (most recent call last):
  File "/opt/hostedtoolcache/Python/3.8.7/x64/lib/python3.8/site-packages/urllib3/connectionpool.py", line 670, in urlopen
    httplib_response = self._make_request(
  File "/opt/hostedtoolcache/Python/3.8.7/x64/lib/python3.8/site-packages/urllib3/connectionpool.py", line 381, in _make_request
    self._validate_conn(conn)
  File "/opt/hostedtoolcache/Python/3.8.7/x64/lib/python3.8/site-packages/urllib3/connectionpool.py", line 978, in _validate_conn
    conn.connect()
  File "/opt/hostedtoolcache/Python/3.8.7/x64/lib/python3.8/site-packages/urllib3/connection.py", line 362, in connect
    self.sock = ssl_wrap_socket(
  File "/opt/hostedtoolcache/Python/3.8.7/x64/lib/python3.8/site-packages/urllib3/util/ssl_.py", line 386, in ssl_wrap_socket
    return context.wrap_socket(sock, server_hostname=server_hostname)
  File "/opt/hostedtoolcache/Python/3.8.7/x64/lib/python3.8/ssl.py", line 500, in wrap_socket
    return self.sslsocket_class._create(
  File "/opt/hostedtoolcache/Python/3.8.7/x64/lib/python3.8/ssl.py", line 1040, in _create
    self.do_handshake()
  File "/opt/hostedtoolcache/Python/3.8.7/x64/lib/python3.8/ssl.py", line 1309, in do_handshake
    self._sslobj.do_handshake()
ssl.SSLEOFError: EOF occurred in violation of protocol (_ssl.c:1125)

During handling of the above exception, another exception occurred:

Traceback (most recent call last):
  File "/opt/hostedtoolcache/Python/3.8.7/x64/lib/python3.8/site-packages/requests/adapters.py", line 439, in send
    resp = conn.urlopen(
  File "/opt/hostedtoolcache/Python/3.8.7/x64/lib/python3.8/site-packages/urllib3/connectionpool.py", line 726, in urlopen
    retries = retries.increment(
  File "/opt/hostedtoolcache/Python/3.8.7/x64/lib/python3.8/site-packages/urllib3/util/retry.py", line 446, in increment
    raise MaxRetryError(_pool, url, error or ResponseError(cause))
urllib3.exceptions.MaxRetryError: HTTPSConnectionPool(host='cert.360.cn', port=443): Max retries exceeded with url: /warning/searchbypage?length=6&start=0 (Caused by SSLError(SSLEOFError(8, 'EOF occurred in violation of protocol (_ssl.c:1125)')))

During handling of the above exception, another exception occurred:

Traceback (most recent call last):
  File "/home/runner/work/threat-broadcast/threat-broadcast/src/crawler/_base_crawler.py", line 62, in cves
    new_cves = self.get_cves()
  File "/home/runner/work/threat-broadcast/threat-broadcast/src/crawler/cert360.py", line 48, in get_cves
    response = requests.get(
  File "/opt/hostedtoolcache/Python/3.8.7/x64/lib/python3.8/site-packages/requests/api.py", line 75, in get
    return request('get', url, params=params, **kwargs)
  File "/opt/hostedtoolcache/Python/3.8.7/x64/lib/python3.8/site-packages/requests/api.py", line 60, in request
    return session.request(method=method, url=url, **kwargs)
  File "/opt/hostedtoolcache/Python/3.8.7/x64/lib/python3.8/site-packages/requests/sessions.py", line 533, in request
    resp = self.send(prep, **send_kwargs)
  File "/opt/hostedtoolcache/Python/3.8.7/x64/lib/python3.8/site-packages/requests/sessions.py", line 646, in send
    r = adapter.send(request, **kwargs)
  File "/opt/hostedtoolcache/Python/3.8.7/x64/lib/python3.8/site-packages/requests/adapters.py", line 514, in send
    raise SSLError(e, request=request)
requests.exceptions.SSLError: HTTPSConnectionPool(host='cert.360.cn', port=443): Max retries exceeded with url: /warning/searchbypage?length=6&start=0 (Caused by SSLError(SSLEOFError(8, 'EOF occurred in violation of protocol (_ssl.c:1125)')))
2021-02-27 15:29:39 [ERROR] : Traceback (most recent call last):
  File "/opt/hostedtoolcache/Python/3.8.7/x64/lib/python3.8/site-packages/urllib3/connectionpool.py", line 670, in urlopen
    httplib_response = self._make_request(
  File "/opt/hostedtoolcache/Python/3.8.7/x64/lib/python3.8/site-packages/urllib3/connectionpool.py", line 381, in _make_request
    self._validate_conn(conn)
  File "/opt/hostedtoolcache/Python/3.8.7/x64/lib/python3.8/site-packages/urllib3/connectionpool.py", line 978, in _validate_conn
    conn.connect()
  File "/opt/hostedtoolcache/Python/3.8.7/x64/lib/python3.8/site-packages/urllib3/connection.py", line 362, in connect
    self.sock = ssl_wrap_socket(
  File "/opt/hostedtoolcache/Python/3.8.7/x64/lib/python3.8/site-packages/urllib3/util/ssl_.py", line 386, in ssl_wrap_socket
    return context.wrap_socket(sock, server_hostname=server_hostname)
  File "/opt/hostedtoolcache/Python/3.8.7/x64/lib/python3.8/ssl.py", line 500, in wrap_socket
    return self.sslsocket_class._create(
  File "/opt/hostedtoolcache/Python/3.8.7/x64/lib/python3.8/ssl.py", line 1040, in _create
    self.do_handshake()
  File "/opt/hostedtoolcache/Python/3.8.7/x64/lib/python3.8/ssl.py", line 1309, in do_handshake
    self._sslobj.do_handshake()
ssl.SSLEOFError: EOF occurred in violation of protocol (_ssl.c:1125)

During handling of the above exception, another exception occurred:

Traceback (most recent call last):
  File "/opt/hostedtoolcache/Python/3.8.7/x64/lib/python3.8/site-packages/requests/adapters.py", line 439, in send
    resp = conn.urlopen(
  File "/opt/hostedtoolcache/Python/3.8.7/x64/lib/python3.8/site-packages/urllib3/connectionpool.py", line 726, in urlopen
    retries = retries.increment(
  File "/opt/hostedtoolcache/Python/3.8.7/x64/lib/python3.8/site-packages/urllib3/util/retry.py", line 446, in increment
    raise MaxRetryError(_pool, url, error or ResponseError(cause))
urllib3.exceptions.MaxRetryError: HTTPSConnectionPool(host='cert.360.cn', port=443): Max retries exceeded with url: /warning/searchbypage?length=6&start=0 (Caused by SSLError(SSLEOFError(8, 'EOF occurred in violation of protocol (_ssl.c:1125)')))

During handling of the above exception, another exception occurred:

Traceback (most recent call last):
  File "/home/runner/work/threat-broadcast/threat-broadcast/src/crawler/_base_crawler.py", line 62, in cves
    new_cves = self.get_cves()
  File "/home/runner/work/threat-broadcast/threat-broadcast/src/crawler/cert360.py", line 48, in get_cves
    response = requests.get(
  File "/opt/hostedtoolcache/Python/3.8.7/x64/lib/python3.8/site-packages/requests/api.py", line 75, in get
    return request('get', url, params=params, **kwargs)
  File "/opt/hostedtoolcache/Python/3.8.7/x64/lib/python3.8/site-packages/requests/api.py", line 60, in request
    return session.request(method=method, url=url, **kwargs)
  File "/opt/hostedtoolcache/Python/3.8.7/x64/lib/python3.8/site-packages/requests/sessions.py", line 533, in request
    resp = self.send(prep, **send_kwargs)
  File "/opt/hostedtoolcache/Python/3.8.7/x64/lib/python3.8/site-packages/requests/sessions.py", line 646, in send
    r = adapter.send(request, **kwargs)
  File "/opt/hostedtoolcache/Python/3.8.7/x64/lib/python3.8/site-packages/requests/adapters.py", line 514, in send
    raise SSLError(e, request=request)
requests.exceptions.SSLError: HTTPSConnectionPool(host='cert.360.cn', port=443): Max retries exceeded with url: /warning/searchbypage?length=6&start=0 (Caused by SSLError(SSLEOFError(8, 'EOF occurred in violation of protocol (_ssl.c:1125)')))
Traceback (most recent call last):
  File "/opt/hostedtoolcache/Python/3.8.7/x64/lib/python3.8/site-packages/urllib3/connectionpool.py", line 670, in urlopen
    httplib_response = self._make_request(
  File "/opt/hostedtoolcache/Python/3.8.7/x64/lib/python3.8/site-packages/urllib3/connectionpool.py", line 381, in _make_request
    self._validate_conn(conn)
  File "/opt/hostedtoolcache/Python/3.8.7/x64/lib/python3.8/site-packages/urllib3/connectionpool.py", line 978, in _validate_conn
    conn.connect()
  File "/opt/hostedtoolcache/Python/3.8.7/x64/lib/python3.8/site-packages/urllib3/connection.py", line 362, in connect
    self.sock = ssl_wrap_socket(
  File "/opt/hostedtoolcache/Python/3.8.7/x64/lib/python3.8/site-packages/urllib3/util/ssl_.py", line 386, in ssl_wrap_socket
    return context.wrap_socket(sock, server_hostname=server_hostname)
  File "/opt/hostedtoolcache/Python/3.8.7/x64/lib/python3.8/ssl.py", line 500, in wrap_socket
    return self.sslsocket_class._create(
  File "/opt/hostedtoolcache/Python/3.8.7/x64/lib/python3.8/ssl.py", line 1040, in _create
    self.do_handshake()
  File "/opt/hostedtoolcache/Python/3.8.7/x64/lib/python3.8/ssl.py", line 1309, in do_handshake
    self._sslobj.do_handshake()
ssl.SSLEOFError: EOF occurred in violation of protocol (_ssl.c:1125)

During handling of the above exception, another exception occurred:

Traceback (most recent call last):
  File "/opt/hostedtoolcache/Python/3.8.7/x64/lib/python3.8/site-packages/requests/adapters.py", line 439, in send
    resp = conn.urlopen(
  File "/opt/hostedtoolcache/Python/3.8.7/x64/lib/python3.8/site-packages/urllib3/connectionpool.py", line 726, in urlopen
    retries = retries.increment(
  File "/opt/hostedtoolcache/Python/3.8.7/x64/lib/python3.8/site-packages/urllib3/util/retry.py", line 446, in increment
    raise MaxRetryError(_pool, url, error or ResponseError(cause))
urllib3.exceptions.MaxRetryError: HTTPSConnectionPool(host='cert.360.cn', port=443): Max retries exceeded with url: /warning/searchbypage?length=6&start=0 (Caused by SSLError(SSLEOFError(8, 'EOF occurred in violation of protocol (_ssl.c:1125)')))

During handling of the above exception, another exception occurred:

Traceback (most recent call last):
  File "/home/runner/work/threat-broadcast/threat-broadcast/src/crawler/_base_crawler.py", line 62, in cves
    new_cves = self.get_cves()
  File "/home/runner/work/threat-broadcast/threat-broadcast/src/crawler/cert360.py", line 48, in get_cves
    response = requests.get(
  File "/opt/hostedtoolcache/Python/3.8.7/x64/lib/python3.8/site-packages/requests/api.py", line 75, in get
    return request('get', url, params=params, **kwargs)
  File "/opt/hostedtoolcache/Python/3.8.7/x64/lib/python3.8/site-packages/requests/api.py", line 60, in request
    return session.request(method=method, url=url, **kwargs)
  File "/opt/hostedtoolcache/Python/3.8.7/x64/lib/python3.8/site-packages/requests/sessions.py", line 533, in request
    resp = self.send(prep, **send_kwargs)
  File "/opt/hostedtoolcache/Python/3.8.7/x64/lib/python3.8/site-packages/requests/sessions.py", line 646, in send
    r = adapter.send(request, **kwargs)
  File "/opt/hostedtoolcache/Python/3.8.7/x64/lib/python3.8/site-packages/requests/adapters.py", line 514, in send
    raise SSLError(e, request=request)
requests.exceptions.SSLError: HTTPSConnectionPool(host='cert.360.cn', port=443): Max retries exceeded with url: /warning/searchbypage?length=6&start=0 (Caused by SSLError(SSLEOFError(8, 'EOF occurred in violation of protocol (_ssl.c:1125)')))
2021-02-27 15:29:39 [INFO] : 得到 [360] 最新威胁情报 [0] 条
2021-02-27 15:29:39 [INFO] : --------------------------------------------
2021-02-27 15:29:39 [INFO] : ++++++++++++++++++++++++++++++++++++++++++++
2021-02-27 15:29:39 [INFO] : 正在获取 [绿盟] 威胁情报...
2021-02-27 15:29:40 [INFO] : 得到 [绿盟] 最新威胁情报 [0] 条
2021-02-27 15:29:40 [INFO] : --------------------------------------------
2021-02-27 15:29:40 [INFO] : ++++++++++++++++++++++++++++++++++++++++++++
2021-02-27 15:29:40 [INFO] : 正在获取 [奇安信] 威胁情报...
2021-02-27 15:29:46 [INFO] : 得到 [奇安信] 最新威胁情报 [0] 条
2021-02-27 15:29:46 [INFO] : --------------------------------------------
2021-02-27 15:29:46 [INFO] : ++++++++++++++++++++++++++++++++++++++++++++
2021-02-27 15:29:46 [INFO] : 正在获取 [红后] 威胁情报...
2021-02-27 15:29:50 [INFO] : 得到 [红后] 最新威胁情报 [0] 条
2021-02-27 15:29:50 [INFO] : --------------------------------------------
2021-02-27 15:29:50 [INFO] : ++++++++++++++++++++++++++++++++++++++++++++
2021-02-27 15:29:50 [INFO] : 正在获取 [安全客] 威胁情报...
2021-02-27 15:29:53 [INFO] : 得到 [安全客] 最新威胁情报 [0] 条
2021-02-27 15:29:53 [INFO] : --------------------------------------------
2021-02-27 15:29:53 [INFO] : ++++++++++++++++++++++++++++++++++++++++++++
2021-02-27 15:29:53 [INFO] : 正在获取 [斗象] 威胁情报...
2021-02-27 15:30:03 [INFO] : 得到 [斗象] 最新威胁情报 [0] 条
2021-02-27 15:30:03 [INFO] : --------------------------------------------
2021-02-27 15:30:03 [INFO] : ++++++++++++++++++++++++++++++++++++++++++++
2021-02-27 15:30:03 [INFO] : 正在获取 [CNVD] 威胁情报...
2021-02-27 15:30:07 [WARNING] : 获取 [CNVD] 威胁情报失败： [HTTP Error 521]
2021-02-27 15:30:07 [INFO] : 得到 [CNVD] 最新威胁情报 [0] 条
2021-02-27 15:30:07 [INFO] : --------------------------------------------
2021-02-27 16:51:30 [INFO] : ++++++++++++++++++++++++++++++++++++++++++++
2021-02-27 16:51:30 [INFO] : 正在获取 [360] 威胁情报...
2021-02-27 16:51:39 [INFO] : 得到 [360] 最新威胁情报 [0] 条
2021-02-27 16:51:39 [INFO] : --------------------------------------------
2021-02-27 16:51:39 [INFO] : ++++++++++++++++++++++++++++++++++++++++++++
2021-02-27 16:51:39 [INFO] : 正在获取 [绿盟] 威胁情报...
2021-02-27 16:51:40 [INFO] : 得到 [绿盟] 最新威胁情报 [0] 条
2021-02-27 16:51:40 [INFO] : --------------------------------------------
2021-02-27 16:51:40 [INFO] : ++++++++++++++++++++++++++++++++++++++++++++
2021-02-27 16:51:40 [INFO] : 正在获取 [奇安信] 威胁情报...
2021-02-27 16:51:42 [INFO] : 得到 [奇安信] 最新威胁情报 [0] 条
2021-02-27 16:51:42 [INFO] : --------------------------------------------
2021-02-27 16:51:42 [INFO] : ++++++++++++++++++++++++++++++++++++++++++++
2021-02-27 16:51:42 [INFO] : 正在获取 [红后] 威胁情报...
2021-02-27 16:51:44 [INFO] : 得到 [红后] 最新威胁情报 [0] 条
2021-02-27 16:51:44 [INFO] : --------------------------------------------
2021-02-27 16:51:44 [INFO] : ++++++++++++++++++++++++++++++++++++++++++++
2021-02-27 16:51:44 [INFO] : 正在获取 [安全客] 威胁情报...
2021-02-27 16:51:46 [INFO] : 得到 [安全客] 最新威胁情报 [2] 条
2021-02-27 16:51:46 [INFO] : --------------------------------------------
2021-02-27 16:51:46 [INFO] : 
==============================================
[ TITLE ] LightCMS 1.3.4 Cross Site Scripting - CXSecurity.com
[ TIME  ] 2021-02-27 16:51:46
[ CVE   ] CVE-2021-3355
[ SRC   ] 安全客
[ URL   ] https://www.anquanke.com/vul/id/2361199
2021-02-27 16:51:46 [INFO] : 
==============================================
[ TITLE ] Yeastar NeoGate TG400 路径遍历漏洞
[ TIME  ] 2021-02-27 16:51:46
[ CVE   ] CVE-2021-27328
[ SRC   ] 安全客
[ URL   ] https://www.anquanke.com/vul/id/2354320
2021-02-27 16:51:46 [INFO] : ++++++++++++++++++++++++++++++++++++++++++++
2021-02-27 16:51:46 [INFO] : 正在获取 [斗象] 威胁情报...
2021-02-27 16:51:53 [INFO] : 得到 [斗象] 最新威胁情报 [0] 条
2021-02-27 16:51:53 [INFO] : --------------------------------------------
2021-02-27 16:51:53 [INFO] : ++++++++++++++++++++++++++++++++++++++++++++
2021-02-27 16:51:53 [INFO] : 正在获取 [CNVD] 威胁情报...
2021-02-27 16:51:55 [WARNING] : 获取 [CNVD] 威胁情报失败： [HTTP Error 521]
2021-02-27 16:51:55 [INFO] : 得到 [CNVD] 最新威胁情报 [0] 条
2021-02-27 16:51:55 [INFO] : --------------------------------------------
2021-02-27 16:51:55 [INFO] : [邮件] 正在推送威胁情报...
2021-02-27 16:51:55 [INFO] : [邮件] 收件人清单： ['mrxn.net@gmail.com']
2021-02-27 16:51:57 [ERROR] : [邮件] 推送威胁情报失败
Traceback (most recent call last):
  File "/home/runner/work/threat-broadcast/threat-broadcast/src/notice/mail.py", line 47, in to_mail
    smtpObj.login(sender, password)
  File "/opt/hostedtoolcache/Python/3.8.7/x64/lib/python3.8/smtplib.py", line 732, in login
    raise last_exception
  File "/opt/hostedtoolcache/Python/3.8.7/x64/lib/python3.8/smtplib.py", line 721, in login
    (code, resp) = self.auth(
  File "/opt/hostedtoolcache/Python/3.8.7/x64/lib/python3.8/smtplib.py", line 644, in auth
    raise SMTPAuthenticationError(code, resp)
smtplib.SMTPAuthenticationError: (502, b'Invalid input from 10.56.24.54 to newxmesmtplogicsvrszc7.qq.com')
2021-02-27 16:51:57 [ERROR] : Traceback (most recent call last):
  File "/home/runner/work/threat-broadcast/threat-broadcast/src/notice/mail.py", line 47, in to_mail
    smtpObj.login(sender, password)
  File "/opt/hostedtoolcache/Python/3.8.7/x64/lib/python3.8/smtplib.py", line 732, in login
    raise last_exception
  File "/opt/hostedtoolcache/Python/3.8.7/x64/lib/python3.8/smtplib.py", line 721, in login
    (code, resp) = self.auth(
  File "/opt/hostedtoolcache/Python/3.8.7/x64/lib/python3.8/smtplib.py", line 644, in auth
    raise SMTPAuthenticationError(code, resp)
smtplib.SMTPAuthenticationError: (502, b'Invalid input from 10.56.24.54 to newxmesmtplogicsvrszc7.qq.com')
Traceback (most recent call last):
  File "/home/runner/work/threat-broadcast/threat-broadcast/src/notice/mail.py", line 47, in to_mail
    smtpObj.login(sender, password)
  File "/opt/hostedtoolcache/Python/3.8.7/x64/lib/python3.8/smtplib.py", line 732, in login
    raise last_exception
  File "/opt/hostedtoolcache/Python/3.8.7/x64/lib/python3.8/smtplib.py", line 721, in login
    (code, resp) = self.auth(
  File "/opt/hostedtoolcache/Python/3.8.7/x64/lib/python3.8/smtplib.py", line 644, in auth
    raise SMTPAuthenticationError(code, resp)
smtplib.SMTPAuthenticationError: (502, b'Invalid input from 10.56.24.54 to newxmesmtplogicsvrszc7.qq.com')
