2021-02-27 03:30:53 [INFO] : ++++++++++++++++++++++++++++++++++++++++++++
2021-02-27 03:30:53 [INFO] : 正在获取 [360] 威胁情报...
2021-02-27 03:30:55 [INFO] : 得到 [360] 最新威胁情报 [0] 条
2021-02-27 03:30:55 [INFO] : --------------------------------------------
2021-02-27 03:30:55 [INFO] : ++++++++++++++++++++++++++++++++++++++++++++
2021-02-27 03:30:55 [INFO] : 正在获取 [绿盟] 威胁情报...
2021-02-27 03:31:41 [INFO] : 得到 [绿盟] 最新威胁情报 [0] 条
2021-02-27 03:31:41 [INFO] : --------------------------------------------
2021-02-27 03:31:41 [INFO] : ++++++++++++++++++++++++++++++++++++++++++++
2021-02-27 03:31:41 [INFO] : 正在获取 [奇安信] 威胁情报...
2021-02-27 03:31:43 [INFO] : 得到 [奇安信] 最新威胁情报 [0] 条
2021-02-27 03:31:43 [INFO] : --------------------------------------------
2021-02-27 03:31:43 [INFO] : ++++++++++++++++++++++++++++++++++++++++++++
2021-02-27 03:31:43 [INFO] : 正在获取 [红后] 威胁情报...
2021-02-27 03:31:46 [INFO] : 得到 [红后] 最新威胁情报 [0] 条
2021-02-27 03:31:46 [INFO] : --------------------------------------------
2021-02-27 03:31:46 [INFO] : ++++++++++++++++++++++++++++++++++++++++++++
2021-02-27 03:31:46 [INFO] : 正在获取 [安全客] 威胁情报...
2021-02-27 03:31:49 [INFO] : 得到 [安全客] 最新威胁情报 [0] 条
2021-02-27 03:31:49 [INFO] : --------------------------------------------
2021-02-27 03:31:49 [INFO] : ++++++++++++++++++++++++++++++++++++++++++++
2021-02-27 03:31:49 [INFO] : 正在获取 [斗象] 威胁情报...
2021-02-27 03:31:57 [INFO] : 得到 [斗象] 最新威胁情报 [0] 条
2021-02-27 03:31:57 [INFO] : --------------------------------------------
2021-02-27 03:31:57 [INFO] : ++++++++++++++++++++++++++++++++++++++++++++
2021-02-27 03:31:57 [INFO] : 正在获取 [CNVD] 威胁情报...
2021-02-27 03:31:59 [WARNING] : 获取 [CNVD] 威胁情报失败： [HTTP Error 521]
2021-02-27 03:31:59 [INFO] : 得到 [CNVD] 最新威胁情报 [0] 条
2021-02-27 03:31:59 [INFO] : --------------------------------------------
2021-02-27 04:36:42 [INFO] : ++++++++++++++++++++++++++++++++++++++++++++
2021-02-27 04:36:42 [INFO] : 正在获取 [360] 威胁情报...
2021-02-27 04:36:43 [INFO] : 得到 [360] 最新威胁情报 [0] 条
2021-02-27 04:36:43 [INFO] : --------------------------------------------
2021-02-27 04:36:43 [INFO] : ++++++++++++++++++++++++++++++++++++++++++++
2021-02-27 04:36:43 [INFO] : 正在获取 [绿盟] 威胁情报...
2021-02-27 04:36:44 [INFO] : 得到 [绿盟] 最新威胁情报 [0] 条
2021-02-27 04:36:44 [INFO] : --------------------------------------------
2021-02-27 04:36:44 [INFO] : ++++++++++++++++++++++++++++++++++++++++++++
2021-02-27 04:36:44 [INFO] : 正在获取 [奇安信] 威胁情报...
2021-02-27 04:36:49 [INFO] : 得到 [奇安信] 最新威胁情报 [0] 条
2021-02-27 04:36:49 [INFO] : --------------------------------------------
2021-02-27 04:36:49 [INFO] : ++++++++++++++++++++++++++++++++++++++++++++
2021-02-27 04:36:49 [INFO] : 正在获取 [红后] 威胁情报...
2021-02-27 04:36:51 [INFO] : 得到 [红后] 最新威胁情报 [0] 条
2021-02-27 04:36:51 [INFO] : --------------------------------------------
2021-02-27 04:36:51 [INFO] : ++++++++++++++++++++++++++++++++++++++++++++
2021-02-27 04:36:51 [INFO] : 正在获取 [安全客] 威胁情报...
2021-02-27 04:36:56 [INFO] : 得到 [安全客] 最新威胁情报 [0] 条
2021-02-27 04:36:56 [INFO] : --------------------------------------------
2021-02-27 04:36:56 [INFO] : ++++++++++++++++++++++++++++++++++++++++++++
2021-02-27 04:36:56 [INFO] : 正在获取 [斗象] 威胁情报...
2021-02-27 04:37:03 [INFO] : 得到 [斗象] 最新威胁情报 [0] 条
2021-02-27 04:37:03 [INFO] : --------------------------------------------
2021-02-27 04:37:03 [INFO] : ++++++++++++++++++++++++++++++++++++++++++++
2021-02-27 04:37:03 [INFO] : 正在获取 [CNVD] 威胁情报...
2021-02-27 04:37:05 [WARNING] : 获取 [CNVD] 威胁情报失败： [HTTP Error 521]
2021-02-27 04:37:05 [INFO] : 得到 [CNVD] 最新威胁情报 [0] 条
2021-02-27 04:37:05 [INFO] : --------------------------------------------
2021-02-27 05:28:44 [INFO] : ++++++++++++++++++++++++++++++++++++++++++++
2021-02-27 05:28:44 [INFO] : 正在获取 [360] 威胁情报...
2021-02-27 05:28:45 [INFO] : 得到 [360] 最新威胁情报 [0] 条
2021-02-27 05:28:45 [INFO] : --------------------------------------------
2021-02-27 05:28:45 [INFO] : ++++++++++++++++++++++++++++++++++++++++++++
2021-02-27 05:28:45 [INFO] : 正在获取 [绿盟] 威胁情报...
2021-02-27 05:28:46 [INFO] : 得到 [绿盟] 最新威胁情报 [0] 条
2021-02-27 05:28:46 [INFO] : --------------------------------------------
2021-02-27 05:28:46 [INFO] : ++++++++++++++++++++++++++++++++++++++++++++
2021-02-27 05:28:46 [INFO] : 正在获取 [奇安信] 威胁情报...
2021-02-27 05:28:53 [INFO] : 得到 [奇安信] 最新威胁情报 [0] 条
2021-02-27 05:28:53 [INFO] : --------------------------------------------
2021-02-27 05:28:53 [INFO] : ++++++++++++++++++++++++++++++++++++++++++++
2021-02-27 05:28:53 [INFO] : 正在获取 [红后] 威胁情报...
2021-02-27 05:28:56 [INFO] : 得到 [红后] 最新威胁情报 [0] 条
2021-02-27 05:28:56 [INFO] : --------------------------------------------
2021-02-27 05:28:56 [INFO] : ++++++++++++++++++++++++++++++++++++++++++++
2021-02-27 05:28:56 [INFO] : 正在获取 [安全客] 威胁情报...
2021-02-27 05:29:58 [ERROR] : 获取 [安全客] 威胁情报异常
Traceback (most recent call last):
  File "/opt/hostedtoolcache/Python/3.8.7/x64/lib/python3.8/site-packages/urllib3/connectionpool.py", line 381, in _make_request
    self._validate_conn(conn)
  File "/opt/hostedtoolcache/Python/3.8.7/x64/lib/python3.8/site-packages/urllib3/connectionpool.py", line 978, in _validate_conn
    conn.connect()
  File "/opt/hostedtoolcache/Python/3.8.7/x64/lib/python3.8/site-packages/urllib3/connection.py", line 362, in connect
    self.sock = ssl_wrap_socket(
  File "/opt/hostedtoolcache/Python/3.8.7/x64/lib/python3.8/site-packages/urllib3/util/ssl_.py", line 386, in ssl_wrap_socket
    return context.wrap_socket(sock, server_hostname=server_hostname)
  File "/opt/hostedtoolcache/Python/3.8.7/x64/lib/python3.8/ssl.py", line 500, in wrap_socket
    return self.sslsocket_class._create(
  File "/opt/hostedtoolcache/Python/3.8.7/x64/lib/python3.8/ssl.py", line 1040, in _create
    self.do_handshake()
  File "/opt/hostedtoolcache/Python/3.8.7/x64/lib/python3.8/ssl.py", line 1309, in do_handshake
    self._sslobj.do_handshake()
socket.timeout: _ssl.c:1108: The handshake operation timed out

During handling of the above exception, another exception occurred:

Traceback (most recent call last):
  File "/opt/hostedtoolcache/Python/3.8.7/x64/lib/python3.8/site-packages/requests/adapters.py", line 439, in send
    resp = conn.urlopen(
  File "/opt/hostedtoolcache/Python/3.8.7/x64/lib/python3.8/site-packages/urllib3/connectionpool.py", line 726, in urlopen
    retries = retries.increment(
  File "/opt/hostedtoolcache/Python/3.8.7/x64/lib/python3.8/site-packages/urllib3/util/retry.py", line 410, in increment
    raise six.reraise(type(error), error, _stacktrace)
  File "/opt/hostedtoolcache/Python/3.8.7/x64/lib/python3.8/site-packages/urllib3/packages/six.py", line 735, in reraise
    raise value
  File "/opt/hostedtoolcache/Python/3.8.7/x64/lib/python3.8/site-packages/urllib3/connectionpool.py", line 670, in urlopen
    httplib_response = self._make_request(
  File "/opt/hostedtoolcache/Python/3.8.7/x64/lib/python3.8/site-packages/urllib3/connectionpool.py", line 384, in _make_request
    self._raise_timeout(err=e, url=url, timeout_value=conn.timeout)
  File "/opt/hostedtoolcache/Python/3.8.7/x64/lib/python3.8/site-packages/urllib3/connectionpool.py", line 335, in _raise_timeout
    raise ReadTimeoutError(
urllib3.exceptions.ReadTimeoutError: HTTPSConnectionPool(host='www.anquanke.com', port=443): Read timed out. (read timeout=60)

During handling of the above exception, another exception occurred:

Traceback (most recent call last):
  File "/home/runner/work/threat-broadcast/threat-broadcast/src/crawler/_base_crawler.py", line 62, in cves
    new_cves = self.get_cves()
  File "/home/runner/work/threat-broadcast/threat-broadcast/src/crawler/anquanke.py", line 41, in get_cves
    response = requests.get(
  File "/opt/hostedtoolcache/Python/3.8.7/x64/lib/python3.8/site-packages/requests/api.py", line 75, in get
    return request('get', url, params=params, **kwargs)
  File "/opt/hostedtoolcache/Python/3.8.7/x64/lib/python3.8/site-packages/requests/api.py", line 60, in request
    return session.request(method=method, url=url, **kwargs)
  File "/opt/hostedtoolcache/Python/3.8.7/x64/lib/python3.8/site-packages/requests/sessions.py", line 533, in request
    resp = self.send(prep, **send_kwargs)
  File "/opt/hostedtoolcache/Python/3.8.7/x64/lib/python3.8/site-packages/requests/sessions.py", line 646, in send
    r = adapter.send(request, **kwargs)
  File "/opt/hostedtoolcache/Python/3.8.7/x64/lib/python3.8/site-packages/requests/adapters.py", line 529, in send
    raise ReadTimeout(e, request=request)
requests.exceptions.ReadTimeout: HTTPSConnectionPool(host='www.anquanke.com', port=443): Read timed out. (read timeout=60)
2021-02-27 05:29:58 [ERROR] : Traceback (most recent call last):
  File "/opt/hostedtoolcache/Python/3.8.7/x64/lib/python3.8/site-packages/urllib3/connectionpool.py", line 381, in _make_request
    self._validate_conn(conn)
  File "/opt/hostedtoolcache/Python/3.8.7/x64/lib/python3.8/site-packages/urllib3/connectionpool.py", line 978, in _validate_conn
    conn.connect()
  File "/opt/hostedtoolcache/Python/3.8.7/x64/lib/python3.8/site-packages/urllib3/connection.py", line 362, in connect
    self.sock = ssl_wrap_socket(
  File "/opt/hostedtoolcache/Python/3.8.7/x64/lib/python3.8/site-packages/urllib3/util/ssl_.py", line 386, in ssl_wrap_socket
    return context.wrap_socket(sock, server_hostname=server_hostname)
  File "/opt/hostedtoolcache/Python/3.8.7/x64/lib/python3.8/ssl.py", line 500, in wrap_socket
    return self.sslsocket_class._create(
  File "/opt/hostedtoolcache/Python/3.8.7/x64/lib/python3.8/ssl.py", line 1040, in _create
    self.do_handshake()
  File "/opt/hostedtoolcache/Python/3.8.7/x64/lib/python3.8/ssl.py", line 1309, in do_handshake
    self._sslobj.do_handshake()
socket.timeout: _ssl.c:1108: The handshake operation timed out

During handling of the above exception, another exception occurred:

Traceback (most recent call last):
  File "/opt/hostedtoolcache/Python/3.8.7/x64/lib/python3.8/site-packages/requests/adapters.py", line 439, in send
    resp = conn.urlopen(
  File "/opt/hostedtoolcache/Python/3.8.7/x64/lib/python3.8/site-packages/urllib3/connectionpool.py", line 726, in urlopen
    retries = retries.increment(
  File "/opt/hostedtoolcache/Python/3.8.7/x64/lib/python3.8/site-packages/urllib3/util/retry.py", line 410, in increment
    raise six.reraise(type(error), error, _stacktrace)
  File "/opt/hostedtoolcache/Python/3.8.7/x64/lib/python3.8/site-packages/urllib3/packages/six.py", line 735, in reraise
    raise value
  File "/opt/hostedtoolcache/Python/3.8.7/x64/lib/python3.8/site-packages/urllib3/connectionpool.py", line 670, in urlopen
    httplib_response = self._make_request(
  File "/opt/hostedtoolcache/Python/3.8.7/x64/lib/python3.8/site-packages/urllib3/connectionpool.py", line 384, in _make_request
    self._raise_timeout(err=e, url=url, timeout_value=conn.timeout)
  File "/opt/hostedtoolcache/Python/3.8.7/x64/lib/python3.8/site-packages/urllib3/connectionpool.py", line 335, in _raise_timeout
    raise ReadTimeoutError(
urllib3.exceptions.ReadTimeoutError: HTTPSConnectionPool(host='www.anquanke.com', port=443): Read timed out. (read timeout=60)

During handling of the above exception, another exception occurred:

Traceback (most recent call last):
  File "/home/runner/work/threat-broadcast/threat-broadcast/src/crawler/_base_crawler.py", line 62, in cves
    new_cves = self.get_cves()
  File "/home/runner/work/threat-broadcast/threat-broadcast/src/crawler/anquanke.py", line 41, in get_cves
    response = requests.get(
  File "/opt/hostedtoolcache/Python/3.8.7/x64/lib/python3.8/site-packages/requests/api.py", line 75, in get
    return request('get', url, params=params, **kwargs)
  File "/opt/hostedtoolcache/Python/3.8.7/x64/lib/python3.8/site-packages/requests/api.py", line 60, in request
    return session.request(method=method, url=url, **kwargs)
  File "/opt/hostedtoolcache/Python/3.8.7/x64/lib/python3.8/site-packages/requests/sessions.py", line 533, in request
    resp = self.send(prep, **send_kwargs)
  File "/opt/hostedtoolcache/Python/3.8.7/x64/lib/python3.8/site-packages/requests/sessions.py", line 646, in send
    r = adapter.send(request, **kwargs)
  File "/opt/hostedtoolcache/Python/3.8.7/x64/lib/python3.8/site-packages/requests/adapters.py", line 529, in send
    raise ReadTimeout(e, request=request)
requests.exceptions.ReadTimeout: HTTPSConnectionPool(host='www.anquanke.com', port=443): Read timed out. (read timeout=60)
Traceback (most recent call last):
  File "/opt/hostedtoolcache/Python/3.8.7/x64/lib/python3.8/site-packages/urllib3/connectionpool.py", line 381, in _make_request
    self._validate_conn(conn)
  File "/opt/hostedtoolcache/Python/3.8.7/x64/lib/python3.8/site-packages/urllib3/connectionpool.py", line 978, in _validate_conn
    conn.connect()
  File "/opt/hostedtoolcache/Python/3.8.7/x64/lib/python3.8/site-packages/urllib3/connection.py", line 362, in connect
    self.sock = ssl_wrap_socket(
  File "/opt/hostedtoolcache/Python/3.8.7/x64/lib/python3.8/site-packages/urllib3/util/ssl_.py", line 386, in ssl_wrap_socket
    return context.wrap_socket(sock, server_hostname=server_hostname)
  File "/opt/hostedtoolcache/Python/3.8.7/x64/lib/python3.8/ssl.py", line 500, in wrap_socket
    return self.sslsocket_class._create(
  File "/opt/hostedtoolcache/Python/3.8.7/x64/lib/python3.8/ssl.py", line 1040, in _create
    self.do_handshake()
  File "/opt/hostedtoolcache/Python/3.8.7/x64/lib/python3.8/ssl.py", line 1309, in do_handshake
    self._sslobj.do_handshake()
socket.timeout: _ssl.c:1108: The handshake operation timed out

During handling of the above exception, another exception occurred:

Traceback (most recent call last):
  File "/opt/hostedtoolcache/Python/3.8.7/x64/lib/python3.8/site-packages/requests/adapters.py", line 439, in send
    resp = conn.urlopen(
  File "/opt/hostedtoolcache/Python/3.8.7/x64/lib/python3.8/site-packages/urllib3/connectionpool.py", line 726, in urlopen
    retries = retries.increment(
  File "/opt/hostedtoolcache/Python/3.8.7/x64/lib/python3.8/site-packages/urllib3/util/retry.py", line 410, in increment
    raise six.reraise(type(error), error, _stacktrace)
  File "/opt/hostedtoolcache/Python/3.8.7/x64/lib/python3.8/site-packages/urllib3/packages/six.py", line 735, in reraise
    raise value
  File "/opt/hostedtoolcache/Python/3.8.7/x64/lib/python3.8/site-packages/urllib3/connectionpool.py", line 670, in urlopen
    httplib_response = self._make_request(
  File "/opt/hostedtoolcache/Python/3.8.7/x64/lib/python3.8/site-packages/urllib3/connectionpool.py", line 384, in _make_request
    self._raise_timeout(err=e, url=url, timeout_value=conn.timeout)
  File "/opt/hostedtoolcache/Python/3.8.7/x64/lib/python3.8/site-packages/urllib3/connectionpool.py", line 335, in _raise_timeout
    raise ReadTimeoutError(
urllib3.exceptions.ReadTimeoutError: HTTPSConnectionPool(host='www.anquanke.com', port=443): Read timed out. (read timeout=60)

During handling of the above exception, another exception occurred:

Traceback (most recent call last):
  File "/home/runner/work/threat-broadcast/threat-broadcast/src/crawler/_base_crawler.py", line 62, in cves
    new_cves = self.get_cves()
  File "/home/runner/work/threat-broadcast/threat-broadcast/src/crawler/anquanke.py", line 41, in get_cves
    response = requests.get(
  File "/opt/hostedtoolcache/Python/3.8.7/x64/lib/python3.8/site-packages/requests/api.py", line 75, in get
    return request('get', url, params=params, **kwargs)
  File "/opt/hostedtoolcache/Python/3.8.7/x64/lib/python3.8/site-packages/requests/api.py", line 60, in request
    return session.request(method=method, url=url, **kwargs)
  File "/opt/hostedtoolcache/Python/3.8.7/x64/lib/python3.8/site-packages/requests/sessions.py", line 533, in request
    resp = self.send(prep, **send_kwargs)
  File "/opt/hostedtoolcache/Python/3.8.7/x64/lib/python3.8/site-packages/requests/sessions.py", line 646, in send
    r = adapter.send(request, **kwargs)
  File "/opt/hostedtoolcache/Python/3.8.7/x64/lib/python3.8/site-packages/requests/adapters.py", line 529, in send
    raise ReadTimeout(e, request=request)
requests.exceptions.ReadTimeout: HTTPSConnectionPool(host='www.anquanke.com', port=443): Read timed out. (read timeout=60)
2021-02-27 05:29:58 [INFO] : 得到 [安全客] 最新威胁情报 [0] 条
2021-02-27 05:29:58 [INFO] : --------------------------------------------
2021-02-27 05:29:58 [INFO] : ++++++++++++++++++++++++++++++++++++++++++++
2021-02-27 05:29:58 [INFO] : 正在获取 [斗象] 威胁情报...
2021-02-27 05:30:07 [INFO] : 得到 [斗象] 最新威胁情报 [0] 条
2021-02-27 05:30:07 [INFO] : --------------------------------------------
2021-02-27 05:30:07 [INFO] : ++++++++++++++++++++++++++++++++++++++++++++
2021-02-27 05:30:07 [INFO] : 正在获取 [CNVD] 威胁情报...
2021-02-27 05:30:11 [WARNING] : 获取 [CNVD] 威胁情报失败： [HTTP Error 521]
2021-02-27 05:30:11 [INFO] : 得到 [CNVD] 最新威胁情报 [0] 条
2021-02-27 05:30:11 [INFO] : --------------------------------------------
