2021-02-28 12:47:56 [INFO] : ++++++++++++++++++++++++++++++++++++++++++++
2021-02-28 12:47:56 [INFO] : 正在获取 [360] 威胁情报...
2021-02-28 12:48:00 [INFO] : 得到 [360] 最新威胁情报 [0] 条
2021-02-28 12:48:00 [INFO] : --------------------------------------------
2021-02-28 12:48:00 [INFO] : ++++++++++++++++++++++++++++++++++++++++++++
2021-02-28 12:48:00 [INFO] : 正在获取 [绿盟] 威胁情报...
2021-02-28 12:48:01 [INFO] : 得到 [绿盟] 最新威胁情报 [0] 条
2021-02-28 12:48:01 [INFO] : --------------------------------------------
2021-02-28 12:48:01 [INFO] : ++++++++++++++++++++++++++++++++++++++++++++
2021-02-28 12:48:01 [INFO] : 正在获取 [奇安信] 威胁情报...
2021-02-28 12:48:05 [INFO] : 得到 [奇安信] 最新威胁情报 [0] 条
2021-02-28 12:48:05 [INFO] : --------------------------------------------
2021-02-28 12:48:05 [INFO] : ++++++++++++++++++++++++++++++++++++++++++++
2021-02-28 12:48:05 [INFO] : 正在获取 [红后] 威胁情报...
2021-02-28 12:48:07 [INFO] : 得到 [红后] 最新威胁情报 [0] 条
2021-02-28 12:48:07 [INFO] : --------------------------------------------
2021-02-28 12:48:07 [INFO] : ++++++++++++++++++++++++++++++++++++++++++++
2021-02-28 12:48:07 [INFO] : 正在获取 [安全客] 威胁情报...
2021-02-28 12:48:11 [INFO] : 得到 [安全客] 最新威胁情报 [0] 条
2021-02-28 12:48:11 [INFO] : --------------------------------------------
2021-02-28 12:48:11 [INFO] : ++++++++++++++++++++++++++++++++++++++++++++
2021-02-28 12:48:11 [INFO] : 正在获取 [斗象] 威胁情报...
2021-02-28 12:48:22 [INFO] : 得到 [斗象] 最新威胁情报 [0] 条
2021-02-28 12:48:22 [INFO] : --------------------------------------------
2021-02-28 12:48:22 [INFO] : ++++++++++++++++++++++++++++++++++++++++++++
2021-02-28 12:48:22 [INFO] : 正在获取 [CNVD] 威胁情报...
2021-02-28 12:48:25 [WARNING] : 获取 [CNVD] 威胁情报失败： [HTTP Error 521]
2021-02-28 12:48:25 [INFO] : 得到 [CNVD] 最新威胁情报 [0] 条
2021-02-28 12:48:25 [INFO] : --------------------------------------------
2021-02-28 13:18:43 [INFO] : ++++++++++++++++++++++++++++++++++++++++++++
2021-02-28 13:18:43 [INFO] : 正在获取 [360] 威胁情报...
2021-02-28 13:18:48 [INFO] : 得到 [360] 最新威胁情报 [0] 条
2021-02-28 13:18:48 [INFO] : --------------------------------------------
2021-02-28 13:18:48 [INFO] : ++++++++++++++++++++++++++++++++++++++++++++
2021-02-28 13:18:48 [INFO] : 正在获取 [绿盟] 威胁情报...
2021-02-28 13:18:49 [INFO] : 得到 [绿盟] 最新威胁情报 [0] 条
2021-02-28 13:18:49 [INFO] : --------------------------------------------
2021-02-28 13:18:49 [INFO] : ++++++++++++++++++++++++++++++++++++++++++++
2021-02-28 13:18:49 [INFO] : 正在获取 [奇安信] 威胁情报...
2021-02-28 13:18:52 [INFO] : 得到 [奇安信] 最新威胁情报 [0] 条
2021-02-28 13:18:52 [INFO] : --------------------------------------------
2021-02-28 13:18:52 [INFO] : ++++++++++++++++++++++++++++++++++++++++++++
2021-02-28 13:18:52 [INFO] : 正在获取 [红后] 威胁情报...
2021-02-28 13:18:56 [INFO] : 得到 [红后] 最新威胁情报 [0] 条
2021-02-28 13:18:56 [INFO] : --------------------------------------------
2021-02-28 13:18:56 [INFO] : ++++++++++++++++++++++++++++++++++++++++++++
2021-02-28 13:18:56 [INFO] : 正在获取 [安全客] 威胁情报...
2021-02-28 13:18:59 [INFO] : 得到 [安全客] 最新威胁情报 [0] 条
2021-02-28 13:18:59 [INFO] : --------------------------------------------
2021-02-28 13:18:59 [INFO] : ++++++++++++++++++++++++++++++++++++++++++++
2021-02-28 13:18:59 [INFO] : 正在获取 [斗象] 威胁情报...
2021-02-28 13:19:08 [INFO] : 得到 [斗象] 最新威胁情报 [0] 条
2021-02-28 13:19:08 [INFO] : --------------------------------------------
2021-02-28 13:19:08 [INFO] : ++++++++++++++++++++++++++++++++++++++++++++
2021-02-28 13:19:08 [INFO] : 正在获取 [CNVD] 威胁情报...
2021-02-28 13:19:12 [WARNING] : 获取 [CNVD] 威胁情报失败： [HTTP Error 521]
2021-02-28 13:19:12 [INFO] : 得到 [CNVD] 最新威胁情报 [0] 条
2021-02-28 13:19:12 [INFO] : --------------------------------------------
2021-02-28 13:54:23 [INFO] : ++++++++++++++++++++++++++++++++++++++++++++
2021-02-28 13:54:23 [INFO] : 正在获取 [360] 威胁情报...
2021-02-28 13:54:30 [INFO] : 得到 [360] 最新威胁情报 [0] 条
2021-02-28 13:54:30 [INFO] : --------------------------------------------
2021-02-28 13:54:30 [INFO] : ++++++++++++++++++++++++++++++++++++++++++++
2021-02-28 13:54:30 [INFO] : 正在获取 [绿盟] 威胁情报...
2021-02-28 13:54:31 [INFO] : 得到 [绿盟] 最新威胁情报 [0] 条
2021-02-28 13:54:31 [INFO] : --------------------------------------------
2021-02-28 13:54:31 [INFO] : ++++++++++++++++++++++++++++++++++++++++++++
2021-02-28 13:54:31 [INFO] : 正在获取 [奇安信] 威胁情报...
2021-02-28 13:54:33 [INFO] : 得到 [奇安信] 最新威胁情报 [0] 条
2021-02-28 13:54:33 [INFO] : --------------------------------------------
2021-02-28 13:54:33 [INFO] : ++++++++++++++++++++++++++++++++++++++++++++
2021-02-28 13:54:33 [INFO] : 正在获取 [红后] 威胁情报...
2021-02-28 13:54:36 [INFO] : 得到 [红后] 最新威胁情报 [0] 条
2021-02-28 13:54:36 [INFO] : --------------------------------------------
2021-02-28 13:54:36 [INFO] : ++++++++++++++++++++++++++++++++++++++++++++
2021-02-28 13:54:36 [INFO] : 正在获取 [安全客] 威胁情报...
2021-02-28 13:54:43 [INFO] : 得到 [安全客] 最新威胁情报 [0] 条
2021-02-28 13:54:43 [INFO] : --------------------------------------------
2021-02-28 13:54:43 [INFO] : ++++++++++++++++++++++++++++++++++++++++++++
2021-02-28 13:54:43 [INFO] : 正在获取 [斗象] 威胁情报...
2021-02-28 13:54:51 [INFO] : 得到 [斗象] 最新威胁情报 [0] 条
2021-02-28 13:54:51 [INFO] : --------------------------------------------
2021-02-28 13:54:51 [INFO] : ++++++++++++++++++++++++++++++++++++++++++++
2021-02-28 13:54:51 [INFO] : 正在获取 [CNVD] 威胁情报...
2021-02-28 13:55:04 [WARNING] : 获取 [CNVD] 威胁情报失败： [HTTP Error 521]
2021-02-28 13:55:04 [INFO] : 得到 [CNVD] 最新威胁情报 [0] 条
2021-02-28 13:55:04 [INFO] : --------------------------------------------
2021-02-28 14:06:05 [INFO] : ++++++++++++++++++++++++++++++++++++++++++++
2021-02-28 14:06:05 [INFO] : 正在获取 [360] 威胁情报...
2021-02-28 14:06:08 [INFO] : 得到 [360] 最新威胁情报 [0] 条
2021-02-28 14:06:08 [INFO] : --------------------------------------------
2021-02-28 14:06:08 [INFO] : ++++++++++++++++++++++++++++++++++++++++++++
2021-02-28 14:06:08 [INFO] : 正在获取 [绿盟] 威胁情报...
2021-02-28 14:06:12 [INFO] : 得到 [绿盟] 最新威胁情报 [0] 条
2021-02-28 14:06:12 [INFO] : --------------------------------------------
2021-02-28 14:06:12 [INFO] : ++++++++++++++++++++++++++++++++++++++++++++
2021-02-28 14:06:12 [INFO] : 正在获取 [奇安信] 威胁情报...
2021-02-28 14:06:19 [INFO] : 得到 [奇安信] 最新威胁情报 [0] 条
2021-02-28 14:06:19 [INFO] : --------------------------------------------
2021-02-28 14:06:19 [INFO] : ++++++++++++++++++++++++++++++++++++++++++++
2021-02-28 14:06:19 [INFO] : 正在获取 [红后] 威胁情报...
2021-02-28 14:06:21 [INFO] : 得到 [红后] 最新威胁情报 [0] 条
2021-02-28 14:06:21 [INFO] : --------------------------------------------
2021-02-28 14:06:21 [INFO] : ++++++++++++++++++++++++++++++++++++++++++++
2021-02-28 14:06:21 [INFO] : 正在获取 [安全客] 威胁情报...
2021-02-28 14:06:28 [INFO] : 得到 [安全客] 最新威胁情报 [0] 条
2021-02-28 14:06:28 [INFO] : --------------------------------------------
2021-02-28 14:06:28 [INFO] : ++++++++++++++++++++++++++++++++++++++++++++
2021-02-28 14:06:28 [INFO] : 正在获取 [斗象] 威胁情报...
2021-02-28 14:06:36 [INFO] : 得到 [斗象] 最新威胁情报 [0] 条
2021-02-28 14:06:36 [INFO] : --------------------------------------------
2021-02-28 14:06:36 [INFO] : ++++++++++++++++++++++++++++++++++++++++++++
2021-02-28 14:06:36 [INFO] : 正在获取 [CNVD] 威胁情报...
2021-02-28 14:06:41 [ERROR] : 获取 [CNVD] 威胁情报异常
Traceback (most recent call last):
  File "/home/runner/work/threat-broadcast/threat-broadcast/src/crawler/_base_crawler.py", line 64, in cves
    new_cves = self.get_cves()
  File "/home/runner/work/threat-broadcast/threat-broadcast/src/crawler/cnvd.py", line 63, in get_cves
    log.warn('获取 [%s] 威胁情报失败： [HTTP Error %i] 服务器返回内容：[%s]' % (self.NAME_CH(), response.status_code),response.text)
TypeError: not enough arguments for format string
2021-02-28 14:06:41 [ERROR] : Traceback (most recent call last):
  File "/home/runner/work/threat-broadcast/threat-broadcast/src/crawler/_base_crawler.py", line 64, in cves
    new_cves = self.get_cves()
  File "/home/runner/work/threat-broadcast/threat-broadcast/src/crawler/cnvd.py", line 63, in get_cves
    log.warn('获取 [%s] 威胁情报失败： [HTTP Error %i] 服务器返回内容：[%s]' % (self.NAME_CH(), response.status_code),response.text)
TypeError: not enough arguments for format string
Traceback (most recent call last):
  File "/home/runner/work/threat-broadcast/threat-broadcast/src/crawler/_base_crawler.py", line 64, in cves
    new_cves = self.get_cves()
  File "/home/runner/work/threat-broadcast/threat-broadcast/src/crawler/cnvd.py", line 63, in get_cves
    log.warn('获取 [%s] 威胁情报失败： [HTTP Error %i] 服务器返回内容：[%s]' % (self.NAME_CH(), response.status_code),response.text)
TypeError: not enough arguments for format string
2021-02-28 14:06:41 [INFO] : 得到 [CNVD] 最新威胁情报 [0] 条
2021-02-28 14:06:41 [INFO] : --------------------------------------------
2021-02-28 14:18:59 [INFO] : ++++++++++++++++++++++++++++++++++++++++++++
2021-02-28 14:18:59 [INFO] : 正在获取 [360] 威胁情报...
2021-02-28 14:19:02 [INFO] : 得到 [360] 最新威胁情报 [0] 条
2021-02-28 14:19:02 [INFO] : --------------------------------------------
2021-02-28 14:19:02 [INFO] : ++++++++++++++++++++++++++++++++++++++++++++
2021-02-28 14:19:02 [INFO] : 正在获取 [绿盟] 威胁情报...
2021-02-28 14:19:04 [INFO] : 得到 [绿盟] 最新威胁情报 [0] 条
2021-02-28 14:19:04 [INFO] : --------------------------------------------
2021-02-28 14:19:04 [INFO] : ++++++++++++++++++++++++++++++++++++++++++++
2021-02-28 14:19:04 [INFO] : 正在获取 [奇安信] 威胁情报...
2021-02-28 14:19:09 [INFO] : 得到 [奇安信] 最新威胁情报 [0] 条
2021-02-28 14:19:09 [INFO] : --------------------------------------------
2021-02-28 14:19:09 [INFO] : ++++++++++++++++++++++++++++++++++++++++++++
2021-02-28 14:19:09 [INFO] : 正在获取 [红后] 威胁情报...
2021-02-28 14:19:13 [INFO] : 得到 [红后] 最新威胁情报 [0] 条
2021-02-28 14:19:13 [INFO] : --------------------------------------------
2021-02-28 14:19:13 [INFO] : ++++++++++++++++++++++++++++++++++++++++++++
2021-02-28 14:19:13 [INFO] : 正在获取 [安全客] 威胁情报...
2021-02-28 14:19:23 [INFO] : 得到 [安全客] 最新威胁情报 [0] 条
2021-02-28 14:19:23 [INFO] : --------------------------------------------
2021-02-28 14:19:23 [INFO] : ++++++++++++++++++++++++++++++++++++++++++++
2021-02-28 14:19:23 [INFO] : 正在获取 [斗象] 威胁情报...
2021-02-28 14:19:37 [INFO] : 得到 [斗象] 最新威胁情报 [0] 条
2021-02-28 14:19:37 [INFO] : --------------------------------------------
2021-02-28 14:19:37 [INFO] : ++++++++++++++++++++++++++++++++++++++++++++
2021-02-28 14:19:37 [INFO] : 正在获取 [CNVD] 威胁情报...
2021-02-28 14:19:40 [ERROR] : 获取 [CNVD] 威胁情报异常
Traceback (most recent call last):
  File "/home/runner/work/threat-broadcast/threat-broadcast/src/crawler/_base_crawler.py", line 64, in cves
    new_cves = self.get_cves()
  File "/home/runner/work/threat-broadcast/threat-broadcast/src/crawler/cnvd.py", line 63, in get_cves
    log.warn('获取 [%s] 威胁情报失败： [HTTP Error %i] 服务器返回内容：[%s]' % (self.NAME_CH(), response.status_code),response.text)
TypeError: not enough arguments for format string
2021-02-28 14:19:40 [ERROR] : Traceback (most recent call last):
  File "/home/runner/work/threat-broadcast/threat-broadcast/src/crawler/_base_crawler.py", line 64, in cves
    new_cves = self.get_cves()
  File "/home/runner/work/threat-broadcast/threat-broadcast/src/crawler/cnvd.py", line 63, in get_cves
    log.warn('获取 [%s] 威胁情报失败： [HTTP Error %i] 服务器返回内容：[%s]' % (self.NAME_CH(), response.status_code),response.text)
TypeError: not enough arguments for format string
Traceback (most recent call last):
  File "/home/runner/work/threat-broadcast/threat-broadcast/src/crawler/_base_crawler.py", line 64, in cves
    new_cves = self.get_cves()
  File "/home/runner/work/threat-broadcast/threat-broadcast/src/crawler/cnvd.py", line 63, in get_cves
    log.warn('获取 [%s] 威胁情报失败： [HTTP Error %i] 服务器返回内容：[%s]' % (self.NAME_CH(), response.status_code),response.text)
TypeError: not enough arguments for format string
2021-02-28 14:19:40 [INFO] : 得到 [CNVD] 最新威胁情报 [0] 条
2021-02-28 14:19:40 [INFO] : --------------------------------------------
2021-02-28 14:20:32 [INFO] : ++++++++++++++++++++++++++++++++++++++++++++
2021-02-28 14:20:32 [INFO] : 正在获取 [360] 威胁情报...
2021-02-28 14:20:34 [INFO] : 得到 [360] 最新威胁情报 [0] 条
2021-02-28 14:20:34 [INFO] : --------------------------------------------
2021-02-28 14:20:34 [INFO] : ++++++++++++++++++++++++++++++++++++++++++++
2021-02-28 14:20:34 [INFO] : 正在获取 [绿盟] 威胁情报...
2021-02-28 14:20:36 [INFO] : 得到 [绿盟] 最新威胁情报 [0] 条
2021-02-28 14:20:36 [INFO] : --------------------------------------------
2021-02-28 14:20:36 [INFO] : ++++++++++++++++++++++++++++++++++++++++++++
2021-02-28 14:20:36 [INFO] : 正在获取 [奇安信] 威胁情报...
2021-02-28 14:20:38 [INFO] : 得到 [奇安信] 最新威胁情报 [0] 条
2021-02-28 14:20:38 [INFO] : --------------------------------------------
2021-02-28 14:20:38 [INFO] : ++++++++++++++++++++++++++++++++++++++++++++
2021-02-28 14:20:38 [INFO] : 正在获取 [红后] 威胁情报...
2021-02-28 14:20:41 [INFO] : 得到 [红后] 最新威胁情报 [0] 条
2021-02-28 14:20:41 [INFO] : --------------------------------------------
2021-02-28 14:20:41 [INFO] : ++++++++++++++++++++++++++++++++++++++++++++
2021-02-28 14:20:41 [INFO] : 正在获取 [安全客] 威胁情报...
2021-02-28 14:21:43 [ERROR] : 获取 [安全客] 威胁情报异常
Traceback (most recent call last):
  File "/opt/hostedtoolcache/Python/3.8.7/x64/lib/python3.8/site-packages/urllib3/connectionpool.py", line 381, in _make_request
    self._validate_conn(conn)
  File "/opt/hostedtoolcache/Python/3.8.7/x64/lib/python3.8/site-packages/urllib3/connectionpool.py", line 978, in _validate_conn
    conn.connect()
  File "/opt/hostedtoolcache/Python/3.8.7/x64/lib/python3.8/site-packages/urllib3/connection.py", line 362, in connect
    self.sock = ssl_wrap_socket(
  File "/opt/hostedtoolcache/Python/3.8.7/x64/lib/python3.8/site-packages/urllib3/util/ssl_.py", line 386, in ssl_wrap_socket
    return context.wrap_socket(sock, server_hostname=server_hostname)
  File "/opt/hostedtoolcache/Python/3.8.7/x64/lib/python3.8/ssl.py", line 500, in wrap_socket
    return self.sslsocket_class._create(
  File "/opt/hostedtoolcache/Python/3.8.7/x64/lib/python3.8/ssl.py", line 1040, in _create
    self.do_handshake()
  File "/opt/hostedtoolcache/Python/3.8.7/x64/lib/python3.8/ssl.py", line 1309, in do_handshake
    self._sslobj.do_handshake()
socket.timeout: _ssl.c:1108: The handshake operation timed out

During handling of the above exception, another exception occurred:

Traceback (most recent call last):
  File "/opt/hostedtoolcache/Python/3.8.7/x64/lib/python3.8/site-packages/requests/adapters.py", line 439, in send
    resp = conn.urlopen(
  File "/opt/hostedtoolcache/Python/3.8.7/x64/lib/python3.8/site-packages/urllib3/connectionpool.py", line 726, in urlopen
    retries = retries.increment(
  File "/opt/hostedtoolcache/Python/3.8.7/x64/lib/python3.8/site-packages/urllib3/util/retry.py", line 410, in increment
    raise six.reraise(type(error), error, _stacktrace)
  File "/opt/hostedtoolcache/Python/3.8.7/x64/lib/python3.8/site-packages/urllib3/packages/six.py", line 735, in reraise
    raise value
  File "/opt/hostedtoolcache/Python/3.8.7/x64/lib/python3.8/site-packages/urllib3/connectionpool.py", line 670, in urlopen
    httplib_response = self._make_request(
  File "/opt/hostedtoolcache/Python/3.8.7/x64/lib/python3.8/site-packages/urllib3/connectionpool.py", line 384, in _make_request
    self._raise_timeout(err=e, url=url, timeout_value=conn.timeout)
  File "/opt/hostedtoolcache/Python/3.8.7/x64/lib/python3.8/site-packages/urllib3/connectionpool.py", line 335, in _raise_timeout
    raise ReadTimeoutError(
urllib3.exceptions.ReadTimeoutError: HTTPSConnectionPool(host='www.anquanke.com', port=443): Read timed out. (read timeout=60)

During handling of the above exception, another exception occurred:

Traceback (most recent call last):
  File "/home/runner/work/threat-broadcast/threat-broadcast/src/crawler/_base_crawler.py", line 64, in cves
    new_cves = self.get_cves()
  File "/home/runner/work/threat-broadcast/threat-broadcast/src/crawler/anquanke.py", line 41, in get_cves
    response = requests.get(
  File "/opt/hostedtoolcache/Python/3.8.7/x64/lib/python3.8/site-packages/requests/api.py", line 75, in get
    return request('get', url, params=params, **kwargs)
  File "/opt/hostedtoolcache/Python/3.8.7/x64/lib/python3.8/site-packages/requests/api.py", line 60, in request
    return session.request(method=method, url=url, **kwargs)
  File "/opt/hostedtoolcache/Python/3.8.7/x64/lib/python3.8/site-packages/requests/sessions.py", line 533, in request
    resp = self.send(prep, **send_kwargs)
  File "/opt/hostedtoolcache/Python/3.8.7/x64/lib/python3.8/site-packages/requests/sessions.py", line 646, in send
    r = adapter.send(request, **kwargs)
  File "/opt/hostedtoolcache/Python/3.8.7/x64/lib/python3.8/site-packages/requests/adapters.py", line 529, in send
    raise ReadTimeout(e, request=request)
requests.exceptions.ReadTimeout: HTTPSConnectionPool(host='www.anquanke.com', port=443): Read timed out. (read timeout=60)
2021-02-28 14:21:43 [ERROR] : Traceback (most recent call last):
  File "/opt/hostedtoolcache/Python/3.8.7/x64/lib/python3.8/site-packages/urllib3/connectionpool.py", line 381, in _make_request
    self._validate_conn(conn)
  File "/opt/hostedtoolcache/Python/3.8.7/x64/lib/python3.8/site-packages/urllib3/connectionpool.py", line 978, in _validate_conn
    conn.connect()
  File "/opt/hostedtoolcache/Python/3.8.7/x64/lib/python3.8/site-packages/urllib3/connection.py", line 362, in connect
    self.sock = ssl_wrap_socket(
  File "/opt/hostedtoolcache/Python/3.8.7/x64/lib/python3.8/site-packages/urllib3/util/ssl_.py", line 386, in ssl_wrap_socket
    return context.wrap_socket(sock, server_hostname=server_hostname)
  File "/opt/hostedtoolcache/Python/3.8.7/x64/lib/python3.8/ssl.py", line 500, in wrap_socket
    return self.sslsocket_class._create(
  File "/opt/hostedtoolcache/Python/3.8.7/x64/lib/python3.8/ssl.py", line 1040, in _create
    self.do_handshake()
  File "/opt/hostedtoolcache/Python/3.8.7/x64/lib/python3.8/ssl.py", line 1309, in do_handshake
    self._sslobj.do_handshake()
socket.timeout: _ssl.c:1108: The handshake operation timed out

During handling of the above exception, another exception occurred:

Traceback (most recent call last):
  File "/opt/hostedtoolcache/Python/3.8.7/x64/lib/python3.8/site-packages/requests/adapters.py", line 439, in send
    resp = conn.urlopen(
  File "/opt/hostedtoolcache/Python/3.8.7/x64/lib/python3.8/site-packages/urllib3/connectionpool.py", line 726, in urlopen
    retries = retries.increment(
  File "/opt/hostedtoolcache/Python/3.8.7/x64/lib/python3.8/site-packages/urllib3/util/retry.py", line 410, in increment
    raise six.reraise(type(error), error, _stacktrace)
  File "/opt/hostedtoolcache/Python/3.8.7/x64/lib/python3.8/site-packages/urllib3/packages/six.py", line 735, in reraise
    raise value
  File "/opt/hostedtoolcache/Python/3.8.7/x64/lib/python3.8/site-packages/urllib3/connectionpool.py", line 670, in urlopen
    httplib_response = self._make_request(
  File "/opt/hostedtoolcache/Python/3.8.7/x64/lib/python3.8/site-packages/urllib3/connectionpool.py", line 384, in _make_request
    self._raise_timeout(err=e, url=url, timeout_value=conn.timeout)
  File "/opt/hostedtoolcache/Python/3.8.7/x64/lib/python3.8/site-packages/urllib3/connectionpool.py", line 335, in _raise_timeout
    raise ReadTimeoutError(
urllib3.exceptions.ReadTimeoutError: HTTPSConnectionPool(host='www.anquanke.com', port=443): Read timed out. (read timeout=60)

During handling of the above exception, another exception occurred:

Traceback (most recent call last):
  File "/home/runner/work/threat-broadcast/threat-broadcast/src/crawler/_base_crawler.py", line 64, in cves
    new_cves = self.get_cves()
  File "/home/runner/work/threat-broadcast/threat-broadcast/src/crawler/anquanke.py", line 41, in get_cves
    response = requests.get(
  File "/opt/hostedtoolcache/Python/3.8.7/x64/lib/python3.8/site-packages/requests/api.py", line 75, in get
    return request('get', url, params=params, **kwargs)
  File "/opt/hostedtoolcache/Python/3.8.7/x64/lib/python3.8/site-packages/requests/api.py", line 60, in request
    return session.request(method=method, url=url, **kwargs)
  File "/opt/hostedtoolcache/Python/3.8.7/x64/lib/python3.8/site-packages/requests/sessions.py", line 533, in request
    resp = self.send(prep, **send_kwargs)
  File "/opt/hostedtoolcache/Python/3.8.7/x64/lib/python3.8/site-packages/requests/sessions.py", line 646, in send
    r = adapter.send(request, **kwargs)
  File "/opt/hostedtoolcache/Python/3.8.7/x64/lib/python3.8/site-packages/requests/adapters.py", line 529, in send
    raise ReadTimeout(e, request=request)
requests.exceptions.ReadTimeout: HTTPSConnectionPool(host='www.anquanke.com', port=443): Read timed out. (read timeout=60)
Traceback (most recent call last):
  File "/opt/hostedtoolcache/Python/3.8.7/x64/lib/python3.8/site-packages/urllib3/connectionpool.py", line 381, in _make_request
    self._validate_conn(conn)
  File "/opt/hostedtoolcache/Python/3.8.7/x64/lib/python3.8/site-packages/urllib3/connectionpool.py", line 978, in _validate_conn
    conn.connect()
  File "/opt/hostedtoolcache/Python/3.8.7/x64/lib/python3.8/site-packages/urllib3/connection.py", line 362, in connect
    self.sock = ssl_wrap_socket(
  File "/opt/hostedtoolcache/Python/3.8.7/x64/lib/python3.8/site-packages/urllib3/util/ssl_.py", line 386, in ssl_wrap_socket
    return context.wrap_socket(sock, server_hostname=server_hostname)
  File "/opt/hostedtoolcache/Python/3.8.7/x64/lib/python3.8/ssl.py", line 500, in wrap_socket
    return self.sslsocket_class._create(
  File "/opt/hostedtoolcache/Python/3.8.7/x64/lib/python3.8/ssl.py", line 1040, in _create
    self.do_handshake()
  File "/opt/hostedtoolcache/Python/3.8.7/x64/lib/python3.8/ssl.py", line 1309, in do_handshake
    self._sslobj.do_handshake()
socket.timeout: _ssl.c:1108: The handshake operation timed out

During handling of the above exception, another exception occurred:

Traceback (most recent call last):
  File "/opt/hostedtoolcache/Python/3.8.7/x64/lib/python3.8/site-packages/requests/adapters.py", line 439, in send
    resp = conn.urlopen(
  File "/opt/hostedtoolcache/Python/3.8.7/x64/lib/python3.8/site-packages/urllib3/connectionpool.py", line 726, in urlopen
    retries = retries.increment(
  File "/opt/hostedtoolcache/Python/3.8.7/x64/lib/python3.8/site-packages/urllib3/util/retry.py", line 410, in increment
    raise six.reraise(type(error), error, _stacktrace)
  File "/opt/hostedtoolcache/Python/3.8.7/x64/lib/python3.8/site-packages/urllib3/packages/six.py", line 735, in reraise
    raise value
  File "/opt/hostedtoolcache/Python/3.8.7/x64/lib/python3.8/site-packages/urllib3/connectionpool.py", line 670, in urlopen
    httplib_response = self._make_request(
  File "/opt/hostedtoolcache/Python/3.8.7/x64/lib/python3.8/site-packages/urllib3/connectionpool.py", line 384, in _make_request
    self._raise_timeout(err=e, url=url, timeout_value=conn.timeout)
  File "/opt/hostedtoolcache/Python/3.8.7/x64/lib/python3.8/site-packages/urllib3/connectionpool.py", line 335, in _raise_timeout
    raise ReadTimeoutError(
urllib3.exceptions.ReadTimeoutError: HTTPSConnectionPool(host='www.anquanke.com', port=443): Read timed out. (read timeout=60)

During handling of the above exception, another exception occurred:

Traceback (most recent call last):
  File "/home/runner/work/threat-broadcast/threat-broadcast/src/crawler/_base_crawler.py", line 64, in cves
    new_cves = self.get_cves()
  File "/home/runner/work/threat-broadcast/threat-broadcast/src/crawler/anquanke.py", line 41, in get_cves
    response = requests.get(
  File "/opt/hostedtoolcache/Python/3.8.7/x64/lib/python3.8/site-packages/requests/api.py", line 75, in get
    return request('get', url, params=params, **kwargs)
  File "/opt/hostedtoolcache/Python/3.8.7/x64/lib/python3.8/site-packages/requests/api.py", line 60, in request
    return session.request(method=method, url=url, **kwargs)
  File "/opt/hostedtoolcache/Python/3.8.7/x64/lib/python3.8/site-packages/requests/sessions.py", line 533, in request
    resp = self.send(prep, **send_kwargs)
  File "/opt/hostedtoolcache/Python/3.8.7/x64/lib/python3.8/site-packages/requests/sessions.py", line 646, in send
    r = adapter.send(request, **kwargs)
  File "/opt/hostedtoolcache/Python/3.8.7/x64/lib/python3.8/site-packages/requests/adapters.py", line 529, in send
    raise ReadTimeout(e, request=request)
requests.exceptions.ReadTimeout: HTTPSConnectionPool(host='www.anquanke.com', port=443): Read timed out. (read timeout=60)
2021-02-28 14:21:43 [INFO] : 得到 [安全客] 最新威胁情报 [0] 条
2021-02-28 14:21:43 [INFO] : --------------------------------------------
2021-02-28 14:21:43 [INFO] : ++++++++++++++++++++++++++++++++++++++++++++
2021-02-28 14:21:43 [INFO] : 正在获取 [斗象] 威胁情报...
2021-02-28 14:21:54 [INFO] : 得到 [斗象] 最新威胁情报 [0] 条
2021-02-28 14:21:54 [INFO] : --------------------------------------------
2021-02-28 14:21:54 [INFO] : ++++++++++++++++++++++++++++++++++++++++++++
2021-02-28 14:21:54 [INFO] : 正在获取 [CNVD] 威胁情报...
2021-02-28 14:21:57 [WARNING] : 获取 [CNVD] 威胁情报失败： [HTTP Error 521] 服务器返回内容：[<script>document.cookie=('_')+('_')+('j')+('s')+('l')+('_')+('c')+('l')+('e')+('a')+('r')+('a')+('n')+('c')+('e')+('_')+('s')+('=')+(-~0+'')+([2]*(3)+'')+((+true)+'')+(-~(3)+'')+((1+[0])/[2]+'')+(0+1+0+1+'')+(2+'')+(-~{}+'')+(-~{}+'')+(9-1*2+'')+('.')+(1+5+'')+((1+[2])/[2]+'')+(+!+[]+'')+('|')+('-')+(+!+[]+'')+('|')+('l')+((1<<3)+'')+('T')+('N')+(3+4+'')+('E')+('d')+('D')+('S')+('N')+(8+'')+([2]*(3)+'')+(-~[6]+'')+('%')+(1+1+'')+('B')+('s')+('Y')+('y')+('X')+('Z')+('A')+('%')+(0+1+0+1+'')+('F')+('B')+('d')+('z')+('m')+('J')+('A')+('%')+((2^1)+'')+('D')+(';')+('m')+('a')+('x')+('-')+('a')+('g')+('e')+('=')+((1|2)+'')+((1+[2])/[2]+'')+(~~''+'')+((+[])+'')+(';')+('p')+('a')+('t')+('h')+('=')+('/');location.href=location.pathname+location.search</script>]
2021-02-28 14:21:57 [INFO] : 得到 [CNVD] 最新威胁情报 [0] 条
2021-02-28 14:21:57 [INFO] : --------------------------------------------
2021-02-28 15:18:48 [INFO] : ++++++++++++++++++++++++++++++++++++++++++++
2021-02-28 15:18:48 [INFO] : 正在获取 [360] 威胁情报...
2021-02-28 15:18:50 [INFO] : 得到 [360] 最新威胁情报 [0] 条
2021-02-28 15:18:50 [INFO] : --------------------------------------------
2021-02-28 15:18:50 [INFO] : ++++++++++++++++++++++++++++++++++++++++++++
2021-02-28 15:18:50 [INFO] : 正在获取 [绿盟] 威胁情报...
2021-02-28 15:18:51 [INFO] : 得到 [绿盟] 最新威胁情报 [0] 条
2021-02-28 15:18:51 [INFO] : --------------------------------------------
2021-02-28 15:18:51 [INFO] : ++++++++++++++++++++++++++++++++++++++++++++
2021-02-28 15:18:51 [INFO] : 正在获取 [奇安信] 威胁情报...
2021-02-28 15:18:55 [INFO] : 得到 [奇安信] 最新威胁情报 [0] 条
2021-02-28 15:18:55 [INFO] : --------------------------------------------
2021-02-28 15:18:55 [INFO] : ++++++++++++++++++++++++++++++++++++++++++++
2021-02-28 15:18:55 [INFO] : 正在获取 [红后] 威胁情报...
2021-02-28 15:18:57 [INFO] : 得到 [红后] 最新威胁情报 [0] 条
2021-02-28 15:18:57 [INFO] : --------------------------------------------
2021-02-28 15:18:57 [INFO] : ++++++++++++++++++++++++++++++++++++++++++++
2021-02-28 15:18:57 [INFO] : 正在获取 [安全客] 威胁情报...
2021-02-28 15:19:00 [INFO] : 得到 [安全客] 最新威胁情报 [0] 条
2021-02-28 15:19:00 [INFO] : --------------------------------------------
2021-02-28 15:19:00 [INFO] : ++++++++++++++++++++++++++++++++++++++++++++
2021-02-28 15:19:00 [INFO] : 正在获取 [斗象] 威胁情报...
2021-02-28 15:19:08 [INFO] : 得到 [斗象] 最新威胁情报 [0] 条
2021-02-28 15:19:08 [INFO] : --------------------------------------------
2021-02-28 15:19:08 [INFO] : ++++++++++++++++++++++++++++++++++++++++++++
2021-02-28 15:19:08 [INFO] : 正在获取 [CNVD] 威胁情报...
2021-02-28 15:19:11 [WARNING] : 获取 [CNVD] 威胁情报失败： [HTTP Error 521] 服务器返回内容：[<script>document.cookie=('_')+('_')+('j')+('s')+('l')+('_')+('c')+('l')+('e')+('a')+('r')+('a')+('n')+('c')+('e')+('_')+('s')+('=')+(-~false+'')+(6+'')+((+true)+'')+((2<<1)+'')+(([2]+0>>2)+'')+(2+'')+(([2]+0>>2)+'')+(-~(4)+'')+(1+4+'')+(-~false+'')+('.')+(~~[]+'')+(-~(8)+'')+(3+6+'')+('|')+('-')+(+!+[]+'')+('|')+(~~false+'')+('S')+('P')+('e')+('x')+('w')+('h')+('N')+('h')+((1+[2]>>2)+'')+('a')+('W')+('h')+('h')+(-~1+'')+('l')+('r')+('X')+('q')+('S')+(4+5+'')+('D')+('v')+('k')+('K')+('H')+('E')+('%')+(1+2+'')+('D')+(';')+('m')+('a')+('x')+('-')+('a')+('g')+('e')+('=')+(3+'')+(1+5+'')+((+false)+'')+(~~''+'')+(';')+('p')+('a')+('t')+('h')+('=')+('/');location.href=location.pathname+location.search</script>]
2021-02-28 15:19:11 [INFO] : 得到 [CNVD] 最新威胁情报 [0] 条
2021-02-28 15:19:11 [INFO] : --------------------------------------------
